Workbook

Sheet 操作说明
A1: 白酒重构｜20mL棕色瓶统一配液（移液枪+10mL量筒）
A3: 设置项目 | B3: 数值 | C3: 说明
A4: 每份酒样最终目标体积mL | B4: 20 | C4: 本工作簿固定以20mL计算；10mL成品需重新缩放
A5: 每一级样品数 | B5: 16 | C5: 每级16份20mL酒样；按20mL主母液及20mL子液核对备液量
A6: 乙醇原液体积分数 | B6: 0.95 | C6: 食用乙醇，假设95%v/v
A7: 名义最终乙醇体积分数 | B7: 0.53 | C7: 用10mL量筒配液，最终为名义约53%v/v，非严格定容
A8: 纯品纯度默认值 | B8: 0.97 | C8: 各化合物可在主母液表按瓶签改动
A9: 取液保留小数位 | B9: 1 | C9: 按0.1μL显示；实际受移液枪精度限制
A10: 体积配制方式 | B10: 量筒 + 移液枪 | C10: 仅用P10/P20/P200/P1000取纯品和母液；95%乙醇用10mL量筒分次取用
A12: 更新：24瓶主母液＋7瓶临用液全部配20mL，合计31瓶、620mL。四级样品吸取量不变；均只需要一次稀释。
A14: 实验台操作顺序（无需天平/容量瓶）
A15: 第1步｜准备容器 | B15: 备24个主液编号M01–M24、7个子液编号D01–D07的20mL棕色瓶；若瓶子装满无法摇匀，可先在洁净容器混匀后转移，或改用更大容量容器。
A16: 第2步｜24瓶主母液 | B16: 按「①」H列吸取纯品μL，用P1000分次取大体积纯品；95%乙醇用10mL量筒分次取，按Q列约加mL至名义20mL。每种独立混匀、确认澄清后装瓶。
A17: 第3步｜7瓶一次稀释液 | B17: 按「②」G列从对应主液取μL，按L列用量筒分次加入约需的95%乙醇，配成名义20mL；7份均一步稀释，不做连续梯度稀释。
A18: 第4步｜重构时取液 | B18: 四级目标不变；照「③」表吸取（按每份20mL），同一种化合物共用主液或临用液；第4级空白项不添加。
A19: 第5步｜53%酒精度 | B19: 看「④」每份酒样应额外加的95%乙醇和水的近似体积；不要在已配好20mL基酒后再额外加纯品母液。10mL量筒无法确保53%的准确酒精度。
A20: 第6步｜溶解与保存 | B20: 少量先做53%乙醇中的澄清度小试，关注癸酸乙酯、辛酸乙酯、壬酸乙酯等；酸与缩醛分开储存。水/乙醇混合体积收缩，20mL只是近似体积。
A21: 体积换算公式 | B21: 纯品μL＝目标母液浓度(mg/mL)×20(mL)÷[密度(g/mL)×纯度]。例如乙酸乙酯300mg/mL×20mL÷(0.896×0.97)≈6903.5μL；见「①」H列。
A22: 误差边界 | B22: 所有31瓶按名义20mL配制，可能远高于实际所需总量；20mL棕色瓶装满无混匀空间。误差来自密度、纯度、量筒读数、混合体积收缩和挥发。

Sheet ①24瓶主母液_纯品μL
A1: ①24瓶主母液｜只按μL取纯品，95%乙醇近似补至目标体积
A3: 24瓶主母液均近似配至20mL；纯品直接按H列吸取μL，Q列为95%食用乙醇约加mL。实际纯度和密度请在E/F列修改。量筒配液误差较大。
A4: 主液编号 | B4: 化合物 | C4: 设计浓度mg/mL | D4: 配制总量mL | E4: 比重g/mL | F4: 纯品纯度 | G4: 理论纯品μL | H4: 实际纯品μL | I4: 按实际取液反算mg/mL | J4: 95%载体近似体积分数 | K4: 16份主液使用mL | L4: 配子液消耗mL | M4: 合计用量mL | N4: 配液剩余mL | O4: 容器 | P4: 溶解/配制提醒 | Q4: 95%乙醇约补加mL | R4: 20mL瓶装操作提示
A5: M01 | B5: 异戊酸乙酯 | C5: 30 | D5: 20 | E5: 0.864 | F5: 0.97 | G5: =C5*D5/(E5*F5) -> 715.92211 | H5: =ROUND(G5,0) -> 716 | I5: =H5*E5*F5/D5 -> 30.003264 | J5: =1-H5/(D5*1000) -> 0.9642 | K5: =SUM(IF(③四级吸取表!E5="主",③四级吸取表!F5,0),IF(③四级吸取表!G5="主",③四级吸取表!H5,0),IF(③四级吸取表!I5="主",③四级吸取表!J5,0),IF(③四级吸取表!K5="主",③四级吸取表!L5,0))*操作说明!$B$5/1000 -> 1.8784 | L5: =IFERROR(INDEX(②7瓶一次稀释液!$G$5:$G$11,MATCH(B5,②7瓶一次稀释液!$B$5:$B$11,0))/1000,0) -> 0.2 | M5: =K5+L5 -> 2.0784 | N5: =D5-M5 -> 17.9216 | O5: 20mL棕色瓶 | P5: 先少量乙醇溶解后补液；检验澄清度 | Q5: =D5-H5/1000 -> 19.284 | R5: =IF(H5>1000,"纯品P1000分次取；勿装满后才混匀","先混匀后装瓶；不可直接装满摇匀") -> 先混匀后装瓶；不可直接装满摇匀
A6: M02 | B6: 丁酸乙酯 | C6: 48 | D6: 20 | E6: 0.8735 | F6: 0.97 | G6: =C6*D6/(E6*F6) -> 1133.0174 | H6: =ROUND(G6,0) -> 1133 | I6: =H6*E6*F6/D6 -> 47.999262 | J6: =1-H6/(D6*1000) -> 0.94335 | K6: =SUM(IF(③四级吸取表!E6="主",③四级吸取表!F6,0),IF(③四级吸取表!G6="主",③四级吸取表!H6,0),IF(③四级吸取表!I6="主",③四级吸取表!J6,0),IF(③四级吸取表!K6="主",③四级吸取表!L6,0))*操作说明!$B$5/1000 -> 6.2672 | L6: =IFERROR(INDEX(②7瓶一次稀释液!$G$5:$G$11,MATCH(B6,②7瓶一次稀释液!$B$5:$B$11,0))/1000,0) -> 4 | M6: =K6+L6 -> 10.2672 | N6: =D6-M6 -> 9.7328 | O6: 20mL棕色瓶 | P6: 先少量乙醇溶解后补液；检验澄清度 | Q6: =D6-H6/1000 -> 18.867 | R6: =IF(H6>1000,"纯品P1000分次取；勿装满后才混匀","先混匀后装瓶；不可直接装满摇匀") -> 纯品P1000分次取；勿装满后才混匀
A7: M03 | B7: 乙酸乙酯 | C7: 300 | D7: 20 | E7: 0.896 | F7: 0.97 | G7: =C7*D7/(E7*F7) -> 6903.5346 | H7: =ROUND(G7,0) -> 6904 | I7: =H7*E7*F7/D7 -> 300.02022 | J7: =1-H7/(D7*1000) -> 0.6548 | K7: =SUM(IF(③四级吸取表!E7="主",③四级吸取表!F7,0),IF(③四级吸取表!G7="主",③四级吸取表!H7,0),IF(③四级吸取表!I7="主",③四级吸取表!J7,0),IF(③四级吸取表!K7="主",③四级吸取表!L7,0))*操作说明!$B$5/1000 -> 7.8944 | L7: =IFERROR(INDEX(②7瓶一次稀释液!$G$5:$G$11,MATCH(B7,②7瓶一次稀释液!$B$5:$B$11,0))/1000,0) -> 0 | M7: =K7+L7 -> 7.8944 | N7: =D7-M7 -> 12.1056 | O7: 20mL棕色瓶 | P7: 先少量乙醇溶解后补液；检验澄清度 | Q7: =D7-H7/1000 -> 13.096 | R7: =IF(H7>1000,"纯品P1000分次取；勿装满后才混匀","先混匀后装瓶；不可直接装满摇匀") -> 纯品P1000分次取；勿装满后才混匀
A8: M04 | B8: 辛酸乙酯 | C8: 12 | D8: 20 | E8: 0.8665 | F8: 0.97 | G8: =C8*D8/(E8*F8) -> 285.54262 | H8: =ROUND(G8,0) -> 286 | I8: =H8*E8*F8/D8 -> 12.019222 | J8: =1-H8/(D8*1000) -> 0.9857 | K8: =SUM(IF(③四级吸取表!E8="主",③四级吸取表!F8,0),IF(③四级吸取表!G8="主",③四级吸取表!H8,0),IF(③四级吸取表!I8="主",③四级吸取表!J8,0),IF(③四级吸取表!K8="主",③四级吸取表!L8,0))*操作说明!$B$5/1000 -> 7.1536 | L8: =IFERROR(INDEX(②7瓶一次稀释液!$G$5:$G$11,MATCH(B8,②7瓶一次稀释液!$B$5:$B$11,0))/1000,0) -> 0 | M8: =K8+L8 -> 7.1536 | N8: =D8-M8 -> 12.8464 | O8: 20mL棕色瓶 | P8: 先少量乙醇溶解后补液；检验澄清度 | Q8: =D8-H8/1000 -> 19.714 | R8: =IF(H8>1000,"纯品P1000分次取；勿装满后才混匀","先混匀后装瓶；不可直接装满摇匀") -> 先混匀后装瓶；不可直接装满摇匀
A9: M05 | B9: 戊酸乙酯 | C9: 20 | D9: 20 | E9: 0.8725 | F9: 0.97 | G9: =C9*D9/(E9*F9) -> 472.63167 | H9: =ROUND(G9,0) -> 473 | I9: =H9*E9*F9/D9 -> 20.015586 | J9: =1-H9/(D9*1000) -> 0.97635 | K9: =SUM(IF(③四级吸取表!E9="主",③四级吸取表!F9,0),IF(③四级吸取表!G9="主",③四级吸取表!H9,0),IF(③四级吸取表!I9="主",③四级吸取表!J9,0),IF(③四级吸取表!K9="主",③四级吸取表!L9,0))*操作说明!$B$5/1000 -> 6.0208 | L9: =IFERROR(INDEX(②7瓶一次稀释液!$G$5:$G$11,MATCH(B9,②7瓶一次稀释液!$B$5:$B$11,0))/1000,0) -> 2 | M9: =K9+L9 -> 8.0208 | N9: =D9-M9 -> 11.9792 | O9: 20mL棕色瓶 | P9: 先少量乙醇溶解后补液；检验澄清度 | Q9: =D9-H9/1000 -> 19.527 | R9: =IF(H9>1000,"纯品P1000分次取；勿装满后才混匀","先混匀后装瓶；不可直接装满摇匀") -> 先混匀后装瓶；不可直接装满摇匀
A10: M06 | B10: 庚酸乙酯 | C10: 17 | D10: 20 | E10: 0.8695 | F10: 0.97 | G10: =C10*D10/(E10*F10) -> 403.12302 | H10: =ROUND(G10,0) -> 403 | I10: =H10*E10*F10/D10 -> 16.994812 | J10: =1-H10/(D10*1000) -> 0.97985 | K10: =SUM(IF(③四级吸取表!E10="主",③四级吸取表!F10,0),IF(③四级吸取表!G10="主",③四级吸取表!H10,0),IF(③四级吸取表!I10="主",③四级吸取表!J10,0),IF(③四级吸取表!K10="主",③四级吸取表!L10,0))*操作说明!$B$5/1000 -> 7.5568 | L10: =IFERROR(INDEX(②7瓶一次稀释液!$G$5:$G$11,MATCH(B10,②7瓶一次稀释液!$B$5:$B$11,0))/1000,0) -> 0 | M10: =K10+L10 -> 7.5568 | N10: =D10-M10 -> 12.4432 | O10: 20mL棕色瓶 | P10: 先少量乙醇溶解后补液；检验澄清度 | Q10: =D10-H10/1000 -> 19.597 | R10: =IF(H10>1000,"纯品P1000分次取；勿装满后才混匀","先混匀后装瓶；不可直接装满摇匀") -> 先混匀后装瓶；不可直接装满摇匀
A11: M07 | B11: 己酸异戊酯 | C11: 2 | D11: 20 | E11: 0.8605 | F11: 0.97 | G11: =C11*D11/(E11*F11) -> 47.92227 | H11: =ROUND(G11,0) -> 48 | I11: =H11*E11*F11/D11 -> 2.003244 | J11: =1-H11/(D11*1000) -> 0.9976 | K11: =SUM(IF(③四级吸取表!E11="主",③四级吸取表!F11,0),IF(③四级吸取表!G11="主",③四级吸取表!H11,0),IF(③四级吸取表!I11="主",③四级吸取表!J11,0),IF(③四级吸取表!K11="主",③四级吸取表!L11,0))*操作说明!$B$5/1000 -> 9.6144 | L11: =IFERROR(INDEX(②7瓶一次稀释液!$G$5:$G$11,MATCH(B11,②7瓶一次稀释液!$B$5:$B$11,0))/1000,0) -> 0 | M11: =K11+L11 -> 9.6144 | N11: =D11-M11 -> 10.3856 | O11: 20mL棕色瓶 | P11: 先少量乙醇溶解后补液；检验澄清度 | Q11: =D11-H11/1000 -> 19.952 | R11: =IF(H11>1000,"纯品P1000分次取；勿装满后才混匀","先混匀后装瓶；不可直接装满摇匀") -> 先混匀后装瓶；不可直接装满摇匀
A12: M08 | B12: 乙酸异戊酯 | C12: 40 | D12: 20 | E12: 0.873 | F12: 0.97 | G12: =C12*D12/(E12*F12) -> 944.72196 | H12: =ROUND(G12,0) -> 945 | I12: =H12*E12*F12/D12 -> 40.011772 | J12: =1-H12/(D12*1000) -> 0.95275 | K12: =SUM(IF(③四级吸取表!E12="主",③四级吸取表!F12,0),IF(③四级吸取表!G12="主",③四级吸取表!H12,0),IF(③四级吸取表!I12="主",③四级吸取表!J12,0),IF(③四级吸取表!K12="主",③四级吸取表!L12,0))*操作说明!$B$5/1000 -> 3.8464 | L12: =IFERROR(INDEX(②7瓶一次稀释液!$G$5:$G$11,MATCH(B12,②7瓶一次稀释液!$B$5:$B$11,0))/1000,0) -> 1 | M12: =K12+L12 -> 4.8464 | N12: =D12-M12 -> 15.1536 | O12: 20mL棕色瓶 | P12: 先少量乙醇溶解后补液；检验澄清度 | Q12: =D12-H12/1000 -> 19.055 | R12: =IF(H12>1000,"纯品P1000分次取；勿装满后才混匀","先混匀后装瓶；不可直接装满摇匀") -> 先混匀后装瓶；不可直接装满摇匀
A13: M09 | B13: 乙醛二乙缩醛 | C13: 40 | D13: 20 | E13: 0.8265 | F13: 0.97 | G13: =C13*D13/(E13*F13) -> 997.87328 | H13: =ROUND(G13,0) -> 998 | I13: =H13*E13*F13/D13 -> 40.00508 | J13: =1-H13/(D13*1000) -> 0.9501 | K13: =SUM(IF(③四级吸取表!E13="主",③四级吸取表!F13,0),IF(③四级吸取表!G13="主",③四级吸取表!H13,0),IF(③四级吸取表!I13="主",③四级吸取表!J13,0),IF(③四级吸取表!K13="主",③四级吸取表!L13,0))*操作说明!$B$5/1000 -> 7.184 | L13: =IFERROR(INDEX(②7瓶一次稀释液!$G$5:$G$11,MATCH(B13,②7瓶一次稀释液!$B$5:$B$11,0))/1000,0) -> 0 | M13: =K13+L13 -> 7.184 | N13: =D13-M13 -> 12.816 | O13: 20mL棕色瓶 | P13: 先少量乙醇溶解后补液；检验澄清度 | Q13: =D13-H13/1000 -> 19.002 | R13: =IF(H13>1000,"纯品P1000分次取；勿装满后才混匀","先混匀后装瓶；不可直接装满摇匀") -> 先混匀后装瓶；不可直接装满摇匀
A14: M10 | B14: 异丁酸乙酯 | C14: 10 | D14: 20 | E14: 0.865 | F14: 0.97 | G14: =C14*D14/(E14*F14) -> 238.36482 | H14: =ROUND(G14,0) -> 238 | I14: =H14*E14*F14/D14 -> 9.984695 | J14: =1-H14/(D14*1000) -> 0.9881 | K14: =SUM(IF(③四级吸取表!E14="主",③四级吸取表!F14,0),IF(③四级吸取表!G14="主",③四级吸取表!H14,0),IF(③四级吸取表!I14="主",③四级吸取表!J14,0),IF(③四级吸取表!K14="主",③四级吸取表!L14,0))*操作说明!$B$5/1000 -> 6.2032 | L14: =IFERROR(INDEX(②7瓶一次稀释液!$G$5:$G$11,MATCH(B14,②7瓶一次稀释液!$B$5:$B$11,0))/1000,0) -> 2 | M14: =K14+L14 -> 8.2032 | N14: =D14-M14 -> 11.7968 | O14: 20mL棕色瓶 | P14: 先少量乙醇溶解后补液；检验澄清度 | Q14: =D14-H14/1000 -> 19.762 | R14: =IF(H14>1000,"纯品P1000分次取；勿装满后才混匀","先混匀后装瓶；不可直接装满摇匀") -> 先混匀后装瓶；不可直接装满摇匀
A15: M11 | B15: 癸酸乙酯 | C15: 4 | D15: 20 | E15: 0.8655 | F15: 0.97 | G15: =C15*D15/(E15*F15) -> 95.290846 | H15: =ROUND(G15,0) -> 95 | I15: =H15*E15*F15/D15 -> 3.9877912 | J15: =1-H15/(D15*1000) -> 0.99525 | K15: =SUM(IF(③四级吸取表!E15="主",③四级吸取表!F15,0),IF(③四级吸取表!G15="主",③四级吸取表!H15,0),IF(③四级吸取表!I15="主",③四级吸取表!J15,0),IF(③四级吸取表!K15="主",③四级吸取表!L15,0))*操作说明!$B$5/1000 -> 7.28 | L15: =IFERROR(INDEX(②7瓶一次稀释液!$G$5:$G$11,MATCH(B15,②7瓶一次稀释液!$B$5:$B$11,0))/1000,0) -> 0 | M15: =K15+L15 -> 7.28 | N15: =D15-M15 -> 12.72 | O15: 20mL棕色瓶 | P15: 先少量乙醇溶解后补液；检验澄清度 | Q15: =D15-H15/1000 -> 19.905 | R15: =IF(H15>1000,"纯品P1000分次取；勿装满后才混匀","先混匀后装瓶；不可直接装满摇匀") -> 先混匀后装瓶；不可直接装满摇匀
A16: M12 | B16: 己酸 | C16: 100 | D16: 20 | E16: 0.9255 | F16: 0.97 | G16: =C16*D16/(E16*F16) -> 2227.8289 | H16: =ROUND(G16,0) -> 2228 | I16: =H16*E16*F16/D16 -> 100.00768 | J16: =1-H16/(D16*1000) -> 0.8886 | K16: =SUM(IF(③四级吸取表!E16="主",③四级吸取表!F16,0),IF(③四级吸取表!G16="主",③四级吸取表!H16,0),IF(③四级吸取表!I16="主",③四级吸取表!J16,0),IF(③四级吸取表!K16="主",③四级吸取表!L16,0))*操作说明!$B$5/1000 -> 7.4624 | L16: =IFERROR(INDEX(②7瓶一次稀释液!$G$5:$G$11,MATCH(B16,②7瓶一次稀释液!$B$5:$B$11,0))/1000,0) -> 0 | M16: =K16+L16 -> 7.4624 | N16: =D16-M16 -> 12.5376 | O16: 20mL棕色瓶 | P16: 先少量乙醇溶解后补液；检验澄清度 | Q16: =D16-H16/1000 -> 17.772 | R16: =IF(H16>1000,"纯品P1000分次取；勿装满后才混匀","先混匀后装瓶；不可直接装满摇匀") -> 纯品P1000分次取；勿装满后才混匀
... A28: M24 | B28: 壬酸乙酯 | C28: 5.2 | D28: 20 | E28: 0.865 | F28: 0.97 | G28: =C28*D28/(E28*F28) -> 123.94971 | H28: =ROUND(G28,0) -> 124 | I28: =H28*E28*F28/D28 -> 5.20211 | J28: =1-H28/(D28*1000) -> 0.9938 | K28: =SUM(IF(③四级吸取表!E28="主",③四级吸取表!F28,0),IF(③四级吸取表!G28="主",③四级吸取表!H28,0),IF(③四级吸取表!I28="主",③四级吸取表!J28,0),IF(③四级吸取表!K28="主",③四级吸取表!L28,0))*操作说明!$B$5/1000 -> 8.1952 | L28: =IFERROR(INDEX(②7瓶一次稀释液!$G$5:$G$11,MATCH(B28,②7瓶一次稀释液!$B$5:$B$11,0))/1000,0) -> 0 | M28: =K28+L28 -> 8.1952 | N28: =D28-M28 -> 11.8048 | O28: 20mL棕色瓶 | P28: 先少量乙醇溶解后补液；检验澄清度 | Q28: =D28-H28/1000 -> 19.876 | R28: =IF(H28>1000,"纯品P1000分次取；勿装满后才混匀","先混匀后装瓶；不可直接装满摇匀") -> 先混匀后装瓶；不可直接装满摇匀

Sheet ②7瓶一次稀释液
A1: 0
A3: 7瓶临用液全部配20mL，浓度及四级单次吸取量保持不变；G列按20mL重新计算了从主母液取用的体积（可能需要P1000分次吸取）。
A4: 子液号 | B4: 化合物 | C4: 原主液mg/mL | D4: 稀释倍数 | E4: 子液浓度mg/mL | F4: 子液最终mL | G4: 主母液取μL | H4: 乙醇补液 | I4: 16份子液实际消耗mL | J4: 剩余mL | K4: 推荐容器 | L4: 95%乙醇约补加mL | M4: 实操提示
A5: D01 | B5: 异戊酸乙酯 | C5: =①24瓶主母液_纯品μL!I5 -> 30.003264 | D5: 100 | E5: =C5/D5 -> 0.30003264 | F5: 20 | G5: =1000*F5/D5 -> 200 | H5: 取主液后用10mL量筒分次加入95%乙醇，近似补足20mL | I5: =(③四级吸取表!H5+③四级吸取表!J5+③四级吸取表!L5)*操作说明!$B$5/1000 -> 3.0352 | J5: =F5-I5 -> 16.9648 | K5: 20mL棕色瓶 | L5: =F5-G5/1000 -> 19.8 | M5: =IF(G5>1000,"P1000分次取主液；乙醇两次量取","主液1次吸取；乙醇用量筒分次加入") -> 主液1次吸取；乙醇用量筒分次加入
A6: D02 | B6: 丁酸乙酯 | C6: =①24瓶主母液_纯品μL!I6 -> 47.999262 | D6: 5 | E6: =C6/D6 -> 9.5998524 | F6: 20 | G6: =1000*F6/D6 -> 4000 | H6: 取主液后用10mL量筒分次加入95%乙醇，近似补足20mL | I6: =(③四级吸取表!H6+③四级吸取表!J6+③四级吸取表!L6)*操作说明!$B$5/1000 -> 2.688 | J6: =F6-I6 -> 17.312 | K6: 20mL棕色瓶 | L6: =F6-G6/1000 -> 16 | M6: =IF(G6>1000,"P1000分次取主液；乙醇两次量取","主液1次吸取；乙醇用量筒分次加入") -> P1000分次取主液；乙醇两次量取
A7: D03 | B7: 戊酸乙酯 | C7: =①24瓶主母液_纯品μL!I9 -> 20.015586 | D7: 10 | E7: =C7/D7 -> 2.0015586 | F7: 20 | G7: =1000*F7/D7 -> 2000 | H7: 取主液后用10mL量筒分次加入95%乙醇，近似补足20mL | I7: =(③四级吸取表!H9+③四级吸取表!J9+③四级吸取表!L9)*操作说明!$B$5/1000 -> 2.6688 | J7: =F7-I7 -> 17.3312 | K7: 20mL棕色瓶 | L7: =F7-G7/1000 -> 18 | M7: =IF(G7>1000,"P1000分次取主液；乙醇两次量取","主液1次吸取；乙醇用量筒分次加入") -> P1000分次取主液；乙醇两次量取
A8: D04 | B8: 乙酸异戊酯 | C8: =①24瓶主母液_纯品μL!I12 -> 40.011772 | D8: 20 | E8: =C8/D8 -> 2.0005886 | F8: 20 | G8: =1000*F8/D8 -> 1000 | H8: 取主液后用10mL量筒分次加入95%乙醇，近似补足20mL | I8: =(③四级吸取表!H12+③四级吸取表!J12+③四级吸取表!L12)*操作说明!$B$5/1000 -> 2.7552 | J8: =F8-I8 -> 17.2448 | K8: 20mL棕色瓶 | L8: =F8-G8/1000 -> 19 | M8: =IF(G8>1000,"P1000分次取主液；乙醇两次量取","主液1次吸取；乙醇用量筒分次加入") -> 主液1次吸取；乙醇用量筒分次加入
A9: D05 | B9: 异丁酸乙酯 | C9: =①24瓶主母液_纯品μL!I14 -> 9.984695 | D9: 10 | E9: =C9/D9 -> 0.9984695 | F9: 20 | G9: =1000*F9/D9 -> 2000 | H9: 取主液后用10mL量筒分次加入95%乙醇，近似补足20mL | I9: =(③四级吸取表!H14+③四级吸取表!J14+③四级吸取表!L14)*操作说明!$B$5/1000 -> 2.2512 | J9: =F9-I9 -> 17.7488 | K9: 20mL棕色瓶 | L9: =F9-G9/1000 -> 18 | M9: =IF(G9>1000,"P1000分次取主液；乙醇两次量取","主液1次吸取；乙醇用量筒分次加入") -> P1000分次取主液；乙醇两次量取
A10: D06 | B10: 苯乙酸乙酯 | C10: =①24瓶主母液_纯品μL!I25 -> 20.022231 | D10: 20 | E10: =C10/D10 -> 1.0011115 | F10: 20 | G10: =1000*F10/D10 -> 1000 | H10: 取主液后用10mL量筒分次加入95%乙醇，近似补足20mL | I10: =(③四级吸取表!H25+③四级吸取表!J25+③四级吸取表!L25)*操作说明!$B$5/1000 -> 2.9456 | J10: =F10-I10 -> 17.0544 | K10: 20mL棕色瓶 | L10: =F10-G10/1000 -> 19 | M10: =IF(G10>1000,"P1000分次取主液；乙醇两次量取","主液1次吸取；乙醇用量筒分次加入") -> 主液1次吸取；乙醇用量筒分次加入
A11: D07 | B11: 1-丁醇 | C11: =①24瓶主母液_纯品μL!I26 -> 40.010948 | D11: 20 | E11: =C11/D11 -> 2.0005474 | F11: 20 | G11: =1000*F11/D11 -> 1000 | H11: 取主液后用10mL量筒分次加入95%乙醇，近似补足20mL | I11: =(③四级吸取表!J26)*操作说明!$B$5/1000 -> 0.2048 | J11: =F11-I11 -> 19.7952 | K11: 20mL棕色瓶 | L11: =F11-G11/1000 -> 19 | M11: =IF(G11>1000,"P1000分次取主液；乙醇两次量取","主液1次吸取；乙醇用量筒分次加入") -> 主液1次吸取；乙醇用量筒分次加入

Sheet ③四级吸取表
A1: ③四级吸取表｜直接按每份20mL所需μL执行
A3: 全部母液及临用液现为20mL瓶装，但浓度保持原设计；四级每份20mL酒样的μL取液量不因母液配制总量变化而变化。主=主液；子=子液。
A4: 主液号 | B4: 化合物 | C4: 主液真实浓度mg/mL | D4: 子液浓度mg/mL | E4: 第1级用液 | F4: 第1级μL | G4: 第2级用液 | H4: 第2级μL | I4: 第3级用液 | J4: 第3级μL | K4: 第4级用液 | L4: 第4级μL | M4: 母液数量 | N4: 特别注意
A5: M01 | B5: 异戊酸乙酯 | C5: =①24瓶主母液_纯品μL!I5 -> 30.003264 | D5: =②7瓶一次稀释液!E5 -> 0.30003264 | E5: 主 | F5: =ROUND(176050/(50*C5),1) -> 117.4 | G5: 子 | H5: =ROUND(1795/(50*D5),1) -> 119.7 | I5: 子 | J5: =ROUND(900/(50*D5),1) -> 60 | K5: 子 | L5: =ROUND(150/(50*D5),1) -> 10 | M5: 主+子
A6: M02 | B6: 丁酸乙酯 | C6: =①24瓶主母液_纯品μL!I6 -> 47.999262 | D6: =②7瓶一次稀释液!E6 -> 9.5998524 | E6: 主 | F6: =ROUND(940000/(50*C6),1) -> 391.7 | G6: 子 | H6: =ROUND(63221/(50*D6),1) -> 131.7 | I6: 子 | J6: =ROUND(15000/(50*D6),1) -> 31.3 | K6: 子 | L6: =ROUND(2400/(50*D6),1) -> 5 | M6: 主+子 | N6: 最低级需要约5μL(P10)
A7: M03 | B7: 乙酸乙酯 | C7: =①24瓶主母液_纯品μL!I7 -> 300.02022 | E7: 主 | F7: =ROUND(4661800/(50*C7),1) -> 310.8 | G7: 主 | H7: =ROUND(1750000/(50*C7),1) -> 116.7 | I7: 主 | J7: =ROUND(588550/(50*C7),1) -> 39.2 | K7: 主 | L7: =ROUND(400000/(50*C7),1) -> 26.7 | M7: 仅主
A8: M04 | B8: 辛酸乙酯 | C8: =①24瓶主母液_纯品μL!I8 -> 12.019222 | E8: 主 | F8: =ROUND(247040/(50*C8),1) -> 411.1 | G8: 主 | H8: =ROUND(18000/(50*C8),1) -> 30 | I8: 主 | J8: =ROUND(3600/(50*C8),1) -> 6 | K8: — | M8: 仅主 | N8: 最低级需要约5μL(P10)
A9: M05 | B9: 戊酸乙酯 | C9: =①24瓶主母液_纯品μL!I9 -> 20.015586 | D9: =②7瓶一次稀释液!E7 -> 2.0015586 | E9: 主 | F9: =ROUND(376550/(50*C9),1) -> 376.3 | G9: 子 | H9: =ROUND(12190/(50*D9),1) -> 121.8 | I9: 子 | J9: =ROUND(3750/(50*D9),1) -> 37.5 | K9: 子 | L9: =ROUND(750/(50*D9),1) -> 7.5 | M9: 主+子
A10: M06 | B10: 庚酸乙酯 | C10: =①24瓶主母液_纯品μL!I10 -> 16.994812 | E10: 主 | F10: =ROUND(348671/(50*C10),1) -> 410.3 | G10: 主 | H10: =ROUND(33000/(50*C10),1) -> 38.8 | I10: 主 | J10: =ROUND(11735/(50*C10),1) -> 13.8 | K10: 主 | L10: =ROUND(8000/(50*C10),1) -> 9.4 | M10: 仅主
A11: M07 | B11: 己酸异戊酯 | C11: =①24瓶主母液_纯品μL!I11 -> 2.003244 | E11: 主 | F11: =ROUND(57280/(50*C11),1) -> 571.9 | G11: 主 | H11: =ROUND(2400/(50*C11),1) -> 24 | I11: 主 | J11: =ROUND(500/(50*C11),1) -> 5 | K11: — | M11: 仅主 | N11: 最低级需要约5μL(P10)
A12: M08 | B12: 乙酸异戊酯 | C12: =①24瓶主母液_纯品μL!I12 -> 40.011772 | D12: =②7瓶一次稀释液!E8 -> 2.0005886 | E12: 主 | F12: =ROUND(480980/(50*C12),1) -> 240.4 | G12: 子 | H12: =ROUND(13500/(50*D12),1) -> 135 | I12: 子 | J12: =ROUND(2700/(50*D12),1) -> 27 | K12: 子 | L12: =ROUND(1025/(50*D12),1) -> 10.2 | M12: 主+子
A13: M09 | B13: 乙醛二乙缩醛 | C13: =①24瓶主母液_纯品μL!I13 -> 40.00508 | E13: 主 | F13: =ROUND(784300/(50*C13),1) -> 392.1 | G13: 主 | H13: =ROUND(89806/(50*C13),1) -> 44.9 | I13: 主 | J13: =ROUND(24000/(50*C13),1) -> 12 | K13: — | M13: 仅主
A14: M10 | B14: 异丁酸乙酯 | C14: =①24瓶主母液_纯品μL!I14 -> 9.984695 | D14: =②7瓶一次稀释液!E9 -> 0.9984695 | E14: 主 | F14: =ROUND(193560/(50*C14),1) -> 387.7 | G14: 子 | H14: =ROUND(4971/(50*D14),1) -> 99.6 | I14: 子 | J14: =ROUND(1750/(50*D14),1) -> 35.1 | K14: 子 | L14: =ROUND(300/(50*D14),1) -> 6 | M14: 主+子 | N14: 最低级需要约5μL(P10)
A15: M11 | B15: 癸酸乙酯 | C15: =①24瓶主母液_纯品μL!I15 -> 3.9877912 | E15: 主 | F15: =ROUND(56115/(50*C15),1) -> 281.4 | G15: 主 | H15: =ROUND(25000/(50*C15),1) -> 125.4 | I15: 主 | J15: =ROUND(7500/(50*C15),1) -> 37.6 | K15: 主 | L15: =ROUND(2117/(50*C15),1) -> 10.6 | M15: 仅主
A16: M12 | B16: 己酸 | C16: =①24瓶主母液_纯品μL!I16 -> 100.00768 | E16: 主 | F16: =ROUND(1552320/(50*C16),1) -> 310.4 | G16: 主 | H16: =ROUND(600000/(50*C16),1) -> 120 | I16: 主 | J16: =ROUND(130000/(50*C16),1) -> 26 | K16: 主 | L16: =ROUND(50000/(50*C16),1) -> 10 | M16: 仅主
A17: M13 | B17: 异丁酸 | C17: =①24瓶主母液_纯品μL!I17 -> 6.010411 | E17: 主 | F17: =ROUND(123135/(50*C17),1) -> 409.7 | G17: 主 | H17: =ROUND(22500/(50*C17),1) -> 74.9 | I17: 主 | J17: =ROUND(3000/(50*C17),1) -> 10 | K17: — | M17: 仅主
A18: M14 | B18: 戊酸 | C18: =①24瓶主母液_纯品μL!I18 -> 9.5939062 | E18: 主 | F18: =ROUND(333536/(50*C18),1) -> 695.3 | G18: 主 | H18: =ROUND(30000/(50*C18),1) -> 62.5 | I18: 主 | J18: =ROUND(8600/(50*C18),1) -> 17.9 | K18: 主 | L18: =ROUND(2400/(50*C18),1) -> 5 | M18: 仅主 | N18: 最低级需要约5μL(P10)
A19: M15 | B19: 辛酸 | C19: =①24瓶主母液_纯品μL!I19 -> 16.021005 | E19: 主 | F19: =ROUND(333536/(50*C19),1) -> 416.4 | G19: 主 | H19: =ROUND(30000/(50*C19),1) -> 37.5 | I19: 主 | J19: =ROUND(8600/(50*C19),1) -> 10.7 | K19: 主 | L19: =ROUND(4800/(50*C19),1) -> 6 | M19: 仅主 | N19: 最低级需要约5μL(P10)
A20: M16 | B20: 庚酸 | C20: =①24瓶主母液_纯品μL!I20 -> 10.012219 | E20: 主 | F20: =ROUND(122710/(50*C20),1) -> 245.1 | G20: 主 | H20: =ROUND(36000/(50*C20),1) -> 71.9 | I20: 主 | J20: =ROUND(10000/(50*C20),1) -> 20 | K20: 主 | L20: =ROUND(5495/(50*C20),1) -> 11 | M20: 仅主
A21: M17 | B21: 丁酸 | C21: =①24瓶主母液_纯品μL!I21 -> 29.982312 | E21: 主 | F21: =ROUND(550200/(50*C21),1) -> 367 | G21: 主 | H21: =ROUND(110000/(50*C21),1) -> 73.4 | I21: 主 | J21: =ROUND(41551/(50*C21),1) -> 27.7 | K21: 主 | L21: =ROUND(15000/(50*C21),1) -> 10 | M21: 仅主
A22: M18 | B22: 乙酸 | C22: =①24瓶主母液_纯品μL!I22 -> 149.98392 | E22: 主 | F22: =ROUND(1800500/(50*C22),1) -> 240.1 | G22: 主 | H22: =ROUND(1200000/(50*C22),1) -> 160 | I22: 主 | J22: =ROUND(320000/(50*C22),1) -> 42.7 | K22: 主 | L22: =ROUND(143377/(50*C22),1) -> 19.1 | M22: 仅主
A23: M19 | B23: 异戊酸/3-甲基丁酸 | C23: =①24瓶主母液_纯品μL!I23 -> 3.0074122 | E23: 主 | F23: =ROUND(32300/(50*C23),1) -> 214.8 | G23: 主 | H23: =ROUND(12000/(50*C23),1) -> 79.8 | I23: 主 | J23: =ROUND(5762/(50*C23),1) -> 38.3 | K23: 主 | L23: =ROUND(1800/(50*C23),1) -> 12 | M23: 仅主
A24: M20 | B24: 己酸己酯 | C24: =①24瓶主母液_纯品μL!I24 -> 8.998884 | E24: 主 | F24: =ROUND(195030/(50*C24),1) -> 433.5 | G24: 主 | H24: =ROUND(12000/(50*C24),1) -> 26.7 | I24: 主 | J24: =ROUND(9412/(50*C24),1) -> 20.9 | K24: 主 | L24: =ROUND(2400/(50*C24),1) -> 5.3 | M24: 仅主 | N24: 最低级需要约5μL(P10)
A25: M21 | B25: 苯乙酸乙酯 | C25: =①24瓶主母液_纯品μL!I25 -> 20.022231 | D25: =②7瓶一次稀释液!E10 -> 1.0011115 | E25: 主 | F25: =ROUND(357110/(50*C25),1) -> 356.7 | G25: 子 | H25: =ROUND(6250/(50*D25),1) -> 124.9 | I25: 子 | J25: =ROUND(1962/(50*D25),1) -> 39.2 | K25: 子 | L25: =ROUND(1000/(50*D25),1) -> 20 | M25: 主+子
A26: M22 | B26: 1-丁醇 | C26: =①24瓶主母液_纯品μL!I26 -> 40.010948 | D26: =②7瓶一次稀释液!E11 -> 2.0005474 | E26: 主 | F26: =ROUND(480980/(50*C26),1) -> 240.4 | G26: 主 | H26: =ROUND(120000/(50*C26),1) -> 60 | I26: 子 | J26: =ROUND(1282/(50*D26),1) -> 12.8 | K26: — | M26: 主+子
A27: M23 | B27: 1-己醇 | C27: =①24瓶主母液_纯品μL!I27 -> 20.007414 | E27: 主 | F27: =ROUND(373000/(50*C27),1) -> 372.9 | G27: 主 | H27: =ROUND(64000/(50*C27),1) -> 64 | I27: 主 | J27: =ROUND(29862/(50*C27),1) -> 29.9 | K27: 主 | L27: =ROUND(16000/(50*C27),1) -> 16 | M27: 仅主
A28: M24 | B28: 壬酸乙酯 | C28: =①24瓶主母液_纯品μL!I28 -> 5.20211 | E28: 主 | F28: =ROUND(118700/(50*C28),1) -> 456.4 | G28: 主 | H28: =ROUND(11000/(50*C28),1) -> 42.3 | I28: 主 | J28: =ROUND(2200/(50*C28),1) -> 8.5 | K28: 主 | L28: =ROUND(1305/(50*C28),1) -> 5 | M28: 仅主 | N28: 最低级需要约5μL(P10)

Sheet ④53度估算
A1: ④每份20mL配制53%乙醇：近似酒精度估算
A3: 注意：载体的95%乙醇体积使用“溶液总体积－纯品体积”近似估算，忽略乙醇/水/香气物质混合体积收缩；10mL量筒无法严格控制53%！
A4: 浓度等级 | B4: 该级20mL母/子液合计mL | C4: 带入95%乙醇载体近似mL | D4: 另加95%乙醇近似mL | E4: 另加水近似mL | F4: 总量按算术相加mL | G4: 酒精度近似% | H4: 风险标记 | I4: 说明
A5: 1 | B5: =SUM(③四级吸取表!F5:F28)/1000 -> 8.6498 | C5: =(③四级吸取表!F5/1000)*①24瓶主母液_纯品μL!J5+(③四级吸取表!F6/1000)*①24瓶主母液_纯品μL!J6+(③四级吸取表!F7/1000)*①24瓶主母液_纯品μL!J7+(③四级吸取表!F8/1000)*①24瓶主母液_纯品μL!J8+(③四级吸取表!F9/1000)*①24瓶主母液_纯品μL!J9+(③四级吸取表!F10/1000)*①24瓶主母液_纯品μL!J10+(③四级吸取表!F11/1000)*①24瓶主母液_纯品μL!J11+(③四级吸取表!F12/1000)*①24瓶主母液_纯品μL!J12+(③四级吸取表!F13/1000)*①24瓶主母液_纯品μL!J13+(③四级吸取表!F14/1000)*①24瓶主母液_纯品μL!J14+(③四级吸取表!F15/1000)*①24瓶主母液_纯品μL!J15+(③四级吸取表!F16/1000)*①24瓶主母液_纯品μL!J16+(③四级吸取表!F17/1000)*①24瓶主母液_纯品μL!J17+(③四级吸取表!F18/1000)*①24瓶主母液_纯品μL!J18+(③四级吸取表!F19/1000)*①24瓶主母液_纯品μL!J19+(③四级吸取表!F20/1000)*①24瓶主母液_纯品μL!J20+(③四级吸取表!F21/1000)*①24瓶主母液_纯品μL!J21+(③四级吸取表!F22/1000)*①24瓶主母液_纯品μL!J22+(③四级吸取表!F23/1000)*①24瓶主母液_纯品μL!J23+(③四级吸取表!F24/1000)*①24瓶主母液_纯品μL!J24+(③四级吸取表!F25/1000)*①24瓶主母液_纯品μL!J25+(③四级吸取表!F26/1000)*①24瓶主母液_纯品μL!J26+(③四级吸取表!F27/1000)*①24瓶主母液_纯品μL!J27+(③四级吸取表!F28/1000)*①24瓶主母液_纯品μL!J28 -> 8.3155793 | D5: =(操作说明!$B$4*操作说明!$B$7/操作说明!$B$6)-C5 -> 2.8423154 | E5: =操作说明!$B$4-B5-D5 -> 8.5078846 | F5: =B5+D5+E5 -> 20 | G5: =(C5+D5)*操作说明!$B$6/操作说明!$B$4 -> 0.53 | H5: =IF(OR(D5<0,E5<0),"不可达","名义估算") -> 名义估算 | I5: 额外95%乙醇与水分开量取；混匀后总体积会偏差
A6: 2 | B6: =SUM(③四级吸取表!H5:H28)/1000 -> 1.9855 | C6: =(③四级吸取表!H5/1000)*(1-(1-①24瓶主母液_纯品μL!J5)/②7瓶一次稀释液!D5)+(③四级吸取表!H6/1000)*(1-(1-①24瓶主母液_纯品μL!J6)/②7瓶一次稀释液!D6)+(③四级吸取表!H7/1000)*①24瓶主母液_纯品μL!J7+(③四级吸取表!H8/1000)*①24瓶主母液_纯品μL!J8+(③四级吸取表!H9/1000)*(1-(1-①24瓶主母液_纯品μL!J9)/②7瓶一次稀释液!D7)+(③四级吸取表!H10/1000)*①24瓶主母液_纯品μL!J10+(③四级吸取表!H11/1000)*①24瓶主母液_纯品μL!J11+(③四级吸取表!H12/1000)*(1-(1-①24瓶主母液_纯品μL!J12)/②7瓶一次稀释液!D8)+(③四级吸取表!H13/1000)*①24瓶主母液_纯品μL!J13+(③四级吸取表!H14/1000)*(1-(1-①24瓶主母液_纯品μL!J14)/②7瓶一次稀释液!D9)+(③四级吸取表!H15/1000)*①24瓶主母液_纯品μL!J15+(③四级吸取表!H16/1000)*①24瓶主母液_纯品μL!J16+(③四级吸取表!H17/1000)*①24瓶主母液_纯品μL!J17+(③四级吸取表!H18/1000)*①24瓶主母液_纯品μL!J18+(③四级吸取表!H19/1000)*①24瓶主母液_纯品μL!J19+(③四级吸取表!H20/1000)*①24瓶主母液_纯品μL!J20+(③四级吸取表!H21/1000)*①24瓶主母液_纯品μL!J21+(③四级吸取表!H22/1000)*①24瓶主母液_纯品μL!J22+(③四级吸取表!H23/1000)*①24瓶主母液_纯品μL!J23+(③四级吸取表!H24/1000)*①24瓶主母液_纯品μL!J24+(③四级吸取表!H25/1000)*(1-(1-①24瓶主母液_纯品μL!J25)/②7瓶一次稀释液!D10)+(③四级吸取表!H26/1000)*①24瓶主母液_纯品μL!J26+(③四级吸取表!H27/1000)*①24瓶主母液_纯品μL!J27+(③四级吸取表!H28/1000)*①24瓶主母液_纯品μL!J28 -> 1.8912615 | D6: =(操作说明!$B$4*操作说明!$B$7/操作说明!$B$6)-C6 -> 9.2666333 | E6: =操作说明!$B$4-B6-D6 -> 8.7478667 | F6: =B6+D6+E6 -> 20 | G6: =(C6+D6)*操作说明!$B$6/操作说明!$B$4 -> 0.53 | H6: =IF(OR(D6<0,E6<0),"不可达","名义估算") -> 名义估算 | I6: 额外95%乙醇与水分开量取；混匀后总体积会偏差
A7: 3 | B7: =SUM(③四级吸取表!J5:J28)/1000 -> 0.6091 | C7: =(③四级吸取表!J5/1000)*(1-(1-①24瓶主母液_纯品μL!J5)/②7瓶一次稀释液!D5)+(③四级吸取表!J6/1000)*(1-(1-①24瓶主母液_纯品μL!J6)/②7瓶一次稀释液!D6)+(③四级吸取表!J7/1000)*①24瓶主母液_纯品μL!J7+(③四级吸取表!J8/1000)*①24瓶主母液_纯品μL!J8+(③四级吸取表!J9/1000)*(1-(1-①24瓶主母液_纯品μL!J9)/②7瓶一次稀释液!D7)+(③四级吸取表!J10/1000)*①24瓶主母液_纯品μL!J10+(③四级吸取表!J11/1000)*①24瓶主母液_纯品μL!J11+(③四级吸取表!J12/1000)*(1-(1-①24瓶主母液_纯品μL!J12)/②7瓶一次稀释液!D8)+(③四级吸取表!J13/1000)*①24瓶主母液_纯品μL!J13+(③四级吸取表!J14/1000)*(1-(1-①24瓶主母液_纯品μL!J14)/②7瓶一次稀释液!D9)+(③四级吸取表!J15/1000)*①24瓶主母液_纯品μL!J15+(③四级吸取表!J16/1000)*①24瓶主母液_纯品μL!J16+(③四级吸取表!J17/1000)*①24瓶主母液_纯品μL!J17+(③四级吸取表!J18/1000)*①24瓶主母液_纯品μL!J18+(③四级吸取表!J19/1000)*①24瓶主母液_纯品μL!J19+(③四级吸取表!J20/1000)*①24瓶主母液_纯品μL!J20+(③四级吸取表!J21/1000)*①24瓶主母液_纯品μL!J21+(③四级吸取表!J22/1000)*①24瓶主母液_纯品μL!J22+(③四级吸取表!J23/1000)*①24瓶主母液_纯品μL!J23+(③四级吸取表!J24/1000)*①24瓶主母液_纯品μL!J24+(③四级吸取表!J25/1000)*(1-(1-①24瓶主母液_纯品μL!J25)/②7瓶一次稀释液!D10)+(③四级吸取表!J26/1000)*(1-(1-①24瓶主母液_纯品μL!J26)/②7瓶一次稀释液!D11)+(③四级吸取表!J27/1000)*①24瓶主母液_纯品μL!J27+(③四级吸取表!J28/1000)*①24瓶主母液_纯品μL!J28 -> 0.58185095 | D7: =(操作说明!$B$4*操作说明!$B$7/操作说明!$B$6)-C7 -> 10.576044 | E7: =操作说明!$B$4-B7-D7 -> 8.8148562 | F7: =B7+D7+E7 -> 20 | G7: =(C7+D7)*操作说明!$B$6/操作说明!$B$4 -> 0.53 | H7: =IF(OR(D7<0,E7<0),"不可达","名义估算") -> 名义估算 | I7: 额外95%乙醇与水分开量取；混匀后总体积会偏差
A8: 4 | B8: =SUM(③四级吸取表!L5:L28)/1000 -> 0.2048 | C8: =(③四级吸取表!L5/1000)*(1-(1-①24瓶主母液_纯品μL!J5)/②7瓶一次稀释液!D5)+(③四级吸取表!L6/1000)*(1-(1-①24瓶主母液_纯品μL!J6)/②7瓶一次稀释液!D6)+(③四级吸取表!L7/1000)*①24瓶主母液_纯品μL!J7+(③四级吸取表!L9/1000)*(1-(1-①24瓶主母液_纯品μL!J9)/②7瓶一次稀释液!D7)+(③四级吸取表!L10/1000)*①24瓶主母液_纯品μL!J10+(③四级吸取表!L12/1000)*(1-(1-①24瓶主母液_纯品μL!J12)/②7瓶一次稀释液!D8)+(③四级吸取表!L14/1000)*(1-(1-①24瓶主母液_纯品μL!J14)/②7瓶一次稀释液!D9)+(③四级吸取表!L15/1000)*①24瓶主母液_纯品μL!J15+(③四级吸取表!L16/1000)*①24瓶主母液_纯品μL!J16+(③四级吸取表!L18/1000)*①24瓶主母液_纯品μL!J18+(③四级吸取表!L19/1000)*①24瓶主母液_纯品μL!J19+(③四级吸取表!L20/1000)*①24瓶主母液_纯品μL!J20+(③四级吸取表!L21/1000)*①24瓶主母液_纯品μL!J21+(③四级吸取表!L22/1000)*①24瓶主母液_纯品μL!J22+(③四级吸取表!L23/1000)*①24瓶主母液_纯品μL!J23+(③四级吸取表!L24/1000)*①24瓶主母液_纯品μL!J24+(③四级吸取表!L25/1000)*(1-(1-①24瓶主母液_纯品μL!J25)/②7瓶一次稀释液!D10)+(③四级吸取表!L27/1000)*①24瓶主母液_纯品μL!J27+(③四级吸取表!L28/1000)*①24瓶主母液_纯品μL!J28 -> 0.19014377 | D8: =(操作说明!$B$4*操作说明!$B$7/操作说明!$B$6)-C8 -> 10.967751 | E8: =操作说明!$B$4-B8-D8 -> 8.827449 | F8: =B8+D8+E8 -> 20 | G8: =(C8+D8)*操作说明!$B$6/操作说明!$B$4 -> 0.53 | H8: =IF(OR(D8<0,E8<0),"不可达","名义估算") -> 名义估算 | I8: 额外95%乙醇与水分开量取；混匀后总体积会偏差
A11: 更简便但偏差较大的做法：每级先按D列追加95%乙醇，再按E列加水。若要求酒精度准确，需要酒精计/密度仪或精确体积定容与验证。

Sheet ⑤按级取液明细
A1: ⑤按等级逐项吸取清单｜可筛选/打印直接在实验台使用
A3: 每行=单份20mL应吸取的一个化合物；“16份累计”用来核对母液够不够用。用10mL量筒的最终体积仅为近似。
A4: 浓度等级 | B4: 编号 | C4: 化合物 | D4: 主/子 | E4: 对应瓶号 | F4: 目标ppb | G4: 吸取μL（单份） | H4: 移液枪建议 | I4: 16份累计mL
A5: 1 | B5: 1 | C5: 异戊酸乙酯 | D5: 主 | E5: M01 | F5: 176050 | G5: =③四级吸取表!F5 -> 117.4 | H5: =IF(G5<=10,"P10",IF(G5<=20,"P20",IF(G5<=200,"P200","P1000"))) -> P200 | I5: =G5*操作说明!$B$5/1000 -> 1.8784
A6: 1 | B6: 2 | C6: 丁酸乙酯 | D6: 主 | E6: M02 | F6: 940000 | G6: =③四级吸取表!F6 -> 391.7 | H6: =IF(G6<=10,"P10",IF(G6<=20,"P20",IF(G6<=200,"P200","P1000"))) -> P1000 | I6: =G6*操作说明!$B$5/1000 -> 6.2672
A7: 1 | B7: 3 | C7: 乙酸乙酯 | D7: 主 | E7: M03 | F7: 4661800 | G7: =③四级吸取表!F7 -> 310.8 | H7: =IF(G7<=10,"P10",IF(G7<=20,"P20",IF(G7<=200,"P200","P1000"))) -> P1000 | I7: =G7*操作说明!$B$5/1000 -> 4.9728
A8: 1 | B8: 4 | C8: 辛酸乙酯 | D8: 主 | E8: M04 | F8: 247040 | G8: =③四级吸取表!F8 -> 411.1 | H8: =IF(G8<=10,"P10",IF(G8<=20,"P20",IF(G8<=200,"P200","P1000"))) -> P1000 | I8: =G8*操作说明!$B$5/1000 -> 6.5776
A9: 1 | B9: 5 | C9: 戊酸乙酯 | D9: 主 | E9: M05 | F9: 376550 | G9: =③四级吸取表!F9 -> 376.3 | H9: =IF(G9<=10,"P10",IF(G9<=20,"P20",IF(G9<=200,"P200","P1000"))) -> P1000 | I9: =G9*操作说明!$B$5/1000 -> 6.0208
A10: 1 | B10: 6 | C10: 庚酸乙酯 | D10: 主 | E10: M06 | F10: 348671 | G10: =③四级吸取表!F10 -> 410.3 | H10: =IF(G10<=10,"P10",IF(G10<=20,"P20",IF(G10<=200,"P200","P1000"))) -> P1000 | I10: =G10*操作说明!$B$5/1000 -> 6.5648
A11: 1 | B11: 7 | C11: 己酸异戊酯 | D11: 主 | E11: M07 | F11: 57280 | G11: =③四级吸取表!F11 -> 571.9 | H11: =IF(G11<=10,"P10",IF(G11<=20,"P20",IF(G11<=200,"P200","P1000"))) -> P1000 | I11: =G11*操作说明!$B$5/1000 -> 9.1504
A12: 1 | B12: 8 | C12: 乙酸异戊酯 | D12: 主 | E12: M08 | F12: 480980 | G12: =③四级吸取表!F12 -> 240.4 | H12: =IF(G12<=10,"P10",IF(G12<=20,"P20",IF(G12<=200,"P200","P1000"))) -> P1000 | I12: =G12*操作说明!$B$5/1000 -> 3.8464
A13: 1 | B13: 9 | C13: 乙醛二乙缩醛 | D13: 主 | E13: M09 | F13: 784300 | G13: =③四级吸取表!F13 -> 392.1 | H13: =IF(G13<=10,"P10",IF(G13<=20,"P20",IF(G13<=200,"P200","P1000"))) -> P1000 | I13: =G13*操作说明!$B$5/1000 -> 6.2736
A14: 1 | B14: 10 | C14: 异丁酸乙酯 | D14: 主 | E14: M10 | F14: 193560 | G14: =③四级吸取表!F14 -> 387.7 | H14: =IF(G14<=10,"P10",IF(G14<=20,"P20",IF(G14<=200,"P200","P1000"))) -> P1000 | I14: =G14*操作说明!$B$5/1000 -> 6.2032
A15: 1 | B15: 11 | C15: 癸酸乙酯 | D15: 主 | E15: M11 | F15: 56115 | G15: =③四级吸取表!F15 -> 281.4 | H15: =IF(G15<=10,"P10",IF(G15<=20,"P20",IF(G15<=200,"P200","P1000"))) -> P1000 | I15: =G15*操作说明!$B$5/1000 -> 4.5024
A16: 1 | B16: 12 | C16: 己酸 | D16: 主 | E16: M12 | F16: 1552320 | G16: =③四级吸取表!F16 -> 310.4 | H16: =IF(G16<=10,"P10",IF(G16<=20,"P20",IF(G16<=200,"P200","P1000"))) -> P1000 | I16: =G16*操作说明!$B$5/1000 -> 4.9664
... A28: 1 | B28: 24 | C28: 壬酸乙酯 | D28: 主 | E28: M24 | F28: 118700 | G28: =③四级吸取表!F28 -> 456.4 | H28: =IF(G28<=10,"P10",IF(G28<=20,"P20",IF(G28<=200,"P200","P1000"))) -> P1000 | I28: =G28*操作说明!$B$5/1000 -> 7.3024
A29: 2 | B29: 1 | C29: 异戊酸乙酯 | D29: 子 | E29: D01 | F29: 1795 | G29: =③四级吸取表!H5 -> 119.7 | H29: =IF(G29<=10,"P10",IF(G29<=20,"P20",IF(G29<=200,"P200","P1000"))) -> P200 | I29: =G29*操作说明!$B$5/1000 -> 1.9152
A30: 2 | B30: 2 | C30: 丁酸乙酯 | D30: 子 | E30: D02 | F30: 63221 | G30: =③四级吸取表!H6 -> 131.7 | H30: =IF(G30<=10,"P10",IF(G30<=20,"P20",IF(G30<=200,"P200","P1000"))) -> P200 | I30: =G30*操作说明!$B$5/1000 -> 2.1072
A31: 2 | B31: 3 | C31: 乙酸乙酯 | D31: 主 | E31: M03 | F31: 1750000 | G31: =③四级吸取表!H7 -> 116.7 | H31: =IF(G31<=10,"P10",IF(G31<=20,"P20",IF(G31<=200,"P200","P1000"))) -> P200 | I31: =G31*操作说明!$B$5/1000 -> 1.8672
A32: 2 | B32: 4 | C32: 辛酸乙酯 | D32: 主 | E32: M04 | F32: 18000 | G32: =③四级吸取表!H8 -> 30 | H32: =IF(G32<=10,"P10",IF(G32<=20,"P20",IF(G32<=200,"P200","P1000"))) -> P200 | I32: =G32*操作说明!$B$5/1000 -> 0.48
A33: 2 | B33: 5 | C33: 戊酸乙酯 | D33: 子 | E33: D03 | F33: 12190 | G33: =③四级吸取表!H9 -> 121.8 | H33: =IF(G33<=10,"P10",IF(G33<=20,"P20",IF(G33<=200,"P200","P1000"))) -> P200 | I33: =G33*操作说明!$B$5/1000 -> 1.9488
A34: 2 | B34: 6 | C34: 庚酸乙酯 | D34: 主 | E34: M06 | F34: 33000 | G34: =③四级吸取表!H10 -> 38.8 | H34: =IF(G34<=10,"P10",IF(G34<=20,"P20",IF(G34<=200,"P200","P1000"))) -> P200 | I34: =G34*操作说明!$B$5/1000 -> 0.6208
A35: 2 | B35: 7 | C35: 己酸异戊酯 | D35: 主 | E35: M07 | F35: 2400 | G35: =③四级吸取表!H11 -> 24 | H35: =IF(G35<=10,"P10",IF(G35<=20,"P20",IF(G35<=200,"P200","P1000"))) -> P200 | I35: =G35*操作说明!$B$5/1000 -> 0.384
A36: 2 | B36: 8 | C36: 乙酸异戊酯 | D36: 子 | E36: D04 | F36: 13500 | G36: =③四级吸取表!H12 -> 135 | H36: =IF(G36<=10,"P10",IF(G36<=20,"P20",IF(G36<=200,"P200","P1000"))) -> P200 | I36: =G36*操作说明!$B$5/1000 -> 2.16
A37: 2 | B37: 9 | C37: 乙醛二乙缩醛 | D37: 主 | E37: M09 | F37: 89806 | G37: =③四级吸取表!H13 -> 44.9 | H37: =IF(G37<=10,"P10",IF(G37<=20,"P20",IF(G37<=200,"P200","P1000"))) -> P200 | I37: =G37*操作说明!$B$5/1000 -> 0.7184
A38: 2 | B38: 10 | C38: 异丁酸乙酯 | D38: 子 | E38: D05 | F38: 4971 | G38: =③四级吸取表!H14 -> 99.6 | H38: =IF(G38<=10,"P10",IF(G38<=20,"P20",IF(G38<=200,"P200","P1000"))) -> P200 | I38: =G38*操作说明!$B$5/1000 -> 1.5936
A39: 2 | B39: 11 | C39: 癸酸乙酯 | D39: 主 | E39: M11 | F39: 25000 | G39: =③四级吸取表!H15 -> 125.4 | H39: =IF(G39<=10,"P10",IF(G39<=20,"P20",IF(G39<=200,"P200","P1000"))) -> P200 | I39: =G39*操作说明!$B$5/1000 -> 2.0064
A40: 2 | B40: 12 | C40: 己酸 | D40: 主 | E40: M12 | F40: 600000 | G40: =③四级吸取表!H16 -> 120 | H40: =IF(G40<=10,"P10",IF(G40<=20,"P20",IF(G40<=200,"P200","P1000"))) -> P200 | I40: =G40*操作说明!$B$5/1000 -> 1.92
... A52: 2 | B52: 24 | C52: 壬酸乙酯 | D52: 主 | E52: M24 | F52: 11000 | G52: =③四级吸取表!H28 -> 42.3 | H52: =IF(G52<=10,"P10",IF(G52<=20,"P20",IF(G52<=200,"P200","P1000"))) -> P200 | I52: =G52*操作说明!$B$5/1000 -> 0.6768
A53: 3 | B53: 1 | C53: 异戊酸乙酯 | D53: 子 | E53: D01 | F53: 900 | G53: =③四级吸取表!J5 -> 60 | H53: =IF(G53<=10,"P10",IF(G53<=20,"P20",IF(G53<=200,"P200","P1000"))) -> P200 | I53: =G53*操作说明!$B$5/1000 -> 0.96
A54: 3 | B54: 2 | C54: 丁酸乙酯 | D54: 子 | E54: D02 | F54: 15000 | G54: =③四级吸取表!J6 -> 31.3 | H54: =IF(G54<=10,"P10",IF(G54<=20,"P20",IF(G54<=200,"P200","P1000"))) -> P200 | I54: =G54*操作说明!$B$5/1000 -> 0.5008
A55: 3 | B55: 3 | C55: 乙酸乙酯 | D55: 主 | E55: M03 | F55: 588550 | G55: =③四级吸取表!J7 -> 39.2 | H55: =IF(G55<=10,"P10",IF(G55<=20,"P20",IF(G55<=200,"P200","P1000"))) -> P200 | I55: =G55*操作说明!$B$5/1000 -> 0.6272
A56: 3 | B56: 4 | C56: 辛酸乙酯 | D56: 主 | E56: M04 | F56: 3600 | G56: =③四级吸取表!J8 -> 6 | H56: =IF(G56<=10,"P10",IF(G56<=20,"P20",IF(G56<=200,"P200","P1000"))) -> P10 | I56: =G56*操作说明!$B$5/1000 -> 0.096
A57: 3 | B57: 5 | C57: 戊酸乙酯 | D57: 子 | E57: D03 | F57: 3750 | G57: =③四级吸取表!J9 -> 37.5 | H57: =IF(G57<=10,"P10",IF(G57<=20,"P20",IF(G57<=200,"P200","P1000"))) -> P200 | I57: =G57*操作说明!$B$5/1000 -> 0.6
A58: 3 | B58: 6 | C58: 庚酸乙酯 | D58: 主 | E58: M06 | F58: 11735 | G58: =③四级吸取表!J10 -> 13.8 | H58: =IF(G58<=10,"P10",IF(G58<=20,"P20",IF(G58<=200,"P200","P1000"))) -> P20 | I58: =G58*操作说明!$B$5/1000 -> 0.2208
A59: 3 | B59: 7 | C59: 己酸异戊酯 | D59: 主 | E59: M07 | F59: 500 | G59: =③四级吸取表!J11 -> 5 | H59: =IF(G59<=10,"P10",IF(G59<=20,"P20",IF(G59<=200,"P200","P1000"))) -> P10 | I59: =G59*操作说明!$B$5/1000 -> 0.08
A60: 3 | B60: 8 | C60: 乙酸异戊酯 | D60: 子 | E60: D04 | F60: 2700 | G60: =③四级吸取表!J12 -> 27 | H60: =IF(G60<=10,"P10",IF(G60<=20,"P20",IF(G60<=200,"P200","P1000"))) -> P200 | I60: =G60*操作说明!$B$5/1000 -> 0.432
A61: 3 | B61: 9 | C61: 乙醛二乙缩醛 | D61: 主 | E61: M09 | F61: 24000 | G61: =③四级吸取表!J13 -> 12 | H61: =IF(G61<=10,"P10",IF(G61<=20,"P20",IF(G61<=200,"P200","P1000"))) -> P20 | I61: =G61*操作说明!$B$5/1000 -> 0.192
A62: 3 | B62: 10 | C62: 异丁酸乙酯 | D62: 子 | E62: D05 | F62: 1750 | G62: =③四级吸取表!J14 -> 35.1 | H62: =IF(G62<=10,"P10",IF(G62<=20,"P20",IF(G62<=200,"P200","P1000"))) -> P200 | I62: =G62*操作说明!$B$5/1000 -> 0.5616
A63: 3 | B63: 11 | C63: 癸酸乙酯 | D63: 主 | E63: M11 | F63: 7500 | G63: =③四级吸取表!J15 -> 37.6 | H63: =IF(G63<=10,"P10",IF(G63<=20,"P20",IF(G63<=200,"P200","P1000"))) -> P200 | I63: =G63*操作说明!$B$5/1000 -> 0.6016
...

Sheet 密度来源
A1: 比重参考值｜FAO/JECFA公开香料规格
A3: FAO/JECFA比重一般为25°C附近，不能代替实物密度标签。数值取来源报告区间中点，均可在主母液表修改。
A4: 编号 | B4: 化合物 | C4: 比重近似 g/mL | D4: 性质/风险 | E4: 来源网址（可打开） | F4: 说明
A5: 1 | B5: 异戊酸乙酯 | C5: 0.864 | D5: 酯类 | E5: https://www.fao.org/food/food-safety-quality/scientific-advice/jecfa/jecfa-flav/details/en/c/202/ | F5: 大多数比重为25°C；忽略比重与密度的细微差别
A6: 2 | B6: 丁酸乙酯 | C6: 0.8735 | D6: 酯类 | E6: https://www.fao.org/food/food-safety-quality/scientific-advice/jecfa/jecfa-flav/details/en/c/314/ | F6: 大多数比重为25°C；忽略比重与密度的细微差别
A7: 3 | B7: 乙酸乙酯 | C7: 0.896 | D7: 高浓度溶液 | E7: https://www.fao.org/food/food-safety-quality/scientific-advice/jecfa/jecfa-flav/details/en/c/312/ | F7: 大多数比重为25°C；忽略比重与密度的细微差别
A8: 4 | B8: 辛酸乙酯 | C8: 0.8665 | D8: 疏水酯 | E8: https://www.fao.org/food/food-safety-quality/scientific-advice/jecfa/jecfa-flav/details/en/c/308/ | F8: 大多数比重为25°C；忽略比重与密度的细微差别
A9: 5 | B9: 戊酸乙酯 | C9: 0.8725 | D9: 酯类 | E9: https://www.fao.org/food/food-safety-quality/scientific-advice/jecfa/jecfa-flav/details/en/c/315/ | F9: 大多数比重为25°C；忽略比重与密度的细微差别
A10: 6 | B10: 庚酸乙酯 | C10: 0.8695 | D10: 疏水酯 | E10: https://www.fao.org/food/food-safety-quality/scientific-advice/jecfa/jecfa-flav/details/en/c/317/ | F10: 大多数比重为25°C；忽略比重与密度的细微差别
A11: 7 | B11: 己酸异戊酯 | C11: 0.8605 | D11: 疏水酯 | E11: https://www.fao.org/food/food-safety-quality/scientific-advice/jecfa/jecfa-flav/details/en/c/295/ | F11: 大多数比重为25°C；忽略比重与密度的细微差别
A12: 8 | B12: 乙酸异戊酯 | C12: 0.873 | D12: 酯类 | E12: https://www.fao.org/food/food-safety-quality/scientific-advice/jecfa/jecfa-flav/details/en/c/307/ | F12: 大多数比重为25°C；忽略比重与密度的细微差别
A13: 9 | B13: 乙醛二乙缩醛 | C13: 0.8265 | D13: 缩醛;与酸分开保存 | E13: https://www.fao.org/food/food-safety-quality/scientific-advice/jecfa/jecfa-flav/details/en/c/729/ | F13: 大多数比重为25°C；忽略比重与密度的细微差别
A14: 10 | B14: 异丁酸乙酯 | C14: 0.865 | D14: 酯类 | E14: https://www.fao.org/food/food-safety-quality/scientific-advice/jecfa/jecfa-flav/details/en/c/214/ | F14: 大多数比重为25°C；忽略比重与密度的细微差别
A15: 11 | B15: 癸酸乙酯 | C15: 0.8655 | D15: 疏水酯 | E15: https://www.fao.org/food/food-safety-quality/scientific-advice/jecfa/jecfa-flav/details/en/c/303/ | F15: 大多数比重为25°C；忽略比重与密度的细微差别
A16: 12 | B16: 己酸 | C16: 0.9255 | D16: 酸类 | E16: https://www.fao.org/food/food-safety-quality/scientific-advice/jecfa/jecfa-flav/details/en/c/265/ | F16: 大多数比重为25°C；忽略比重与密度的细微差别
... A28: 24 | B28: 壬酸乙酯 | C28: 0.865 | D28: 疏水酯 | E28: https://www.fao.org/food/food-safety-quality/scientific-advice/jecfa/jecfa-flav/details/en/c/302/ | F28: 大多数比重为25°C；忽略比重与密度的细微差别

Sheet ⑥20mL逐瓶配制卡
A1: 20mL逐瓶操作卡｜照表吸取，分次加95%食用乙醇
A2: 先吸取纯品或对应母液，再按“乙醇约加mL”用10mL量筒分次补加；每瓶总量仅为近似20mL，不能代替容量瓶准确定容。
A4: 瓶号 | B4: 类型 | C4: 化合物 | D4: 吸取来源 | E4: 需吸取μL | F4: 移液枪取液建议 | G4: 名义最终体积mL | H4: 95%乙醇约加mL | I4: 10mL量筒操作 | J4: 配好打勾
A5: M01 | B5: 主液 | C5: =①24瓶主母液_纯品μL!B5 -> 异戊酸乙酯 | D5: 对应化合物液体纯品 | E5: =①24瓶主母液_纯品μL!H5 -> 716 | F5: =IF(E5>1000,"P1000分次（约"&ROUNDUP(E5/1000,0)&"次）",IF(E5>200,"P1000",IF(E5>20,"P200",IF(E5>10,"P20","P10")))) -> P1000 | G5: =①24瓶主母液_纯品μL!D5 -> 20 | H5: =①24瓶主母液_纯品μL!Q5 -> 19.284 | I5: =IF(H5>10,"先量10mL，再量"&TEXT(H5-10,"0.00")&"mL","一次量"&TEXT(H5,"0.00")&"mL") -> 先量10mL，再量9.28mL | J5: □
A6: M02 | B6: 主液 | C6: =①24瓶主母液_纯品μL!B6 -> 丁酸乙酯 | D6: 对应化合物液体纯品 | E6: =①24瓶主母液_纯品μL!H6 -> 1133 | F6: =IF(E6>1000,"P1000分次（约"&ROUNDUP(E6/1000,0)&"次）",IF(E6>200,"P1000",IF(E6>20,"P200",IF(E6>10,"P20","P10")))) -> P1000分次（约2次） | G6: =①24瓶主母液_纯品μL!D6 -> 20 | H6: =①24瓶主母液_纯品μL!Q6 -> 18.867 | I6: =IF(H6>10,"先量10mL，再量"&TEXT(H6-10,"0.00")&"mL","一次量"&TEXT(H6,"0.00")&"mL") -> 先量10mL，再量8.87mL | J6: □
A7: M03 | B7: 主液 | C7: =①24瓶主母液_纯品μL!B7 -> 乙酸乙酯 | D7: 对应化合物液体纯品 | E7: =①24瓶主母液_纯品μL!H7 -> 6904 | F7: =IF(E7>1000,"P1000分次（约"&ROUNDUP(E7/1000,0)&"次）",IF(E7>200,"P1000",IF(E7>20,"P200",IF(E7>10,"P20","P10")))) -> P1000分次（约7次） | G7: =①24瓶主母液_纯品μL!D7 -> 20 | H7: =①24瓶主母液_纯品μL!Q7 -> 13.096 | I7: =IF(H7>10,"先量10mL，再量"&TEXT(H7-10,"0.00")&"mL","一次量"&TEXT(H7,"0.00")&"mL") -> 先量10mL，再量3.10mL | J7: □
A8: M04 | B8: 主液 | C8: =①24瓶主母液_纯品μL!B8 -> 辛酸乙酯 | D8: 对应化合物液体纯品 | E8: =①24瓶主母液_纯品μL!H8 -> 286 | F8: =IF(E8>1000,"P1000分次（约"&ROUNDUP(E8/1000,0)&"次）",IF(E8>200,"P1000",IF(E8>20,"P200",IF(E8>10,"P20","P10")))) -> P1000 | G8: =①24瓶主母液_纯品μL!D8 -> 20 | H8: =①24瓶主母液_纯品μL!Q8 -> 19.714 | I8: =IF(H8>10,"先量10mL，再量"&TEXT(H8-10,"0.00")&"mL","一次量"&TEXT(H8,"0.00")&"mL") -> 先量10mL，再量9.71mL | J8: □
A9: M05 | B9: 主液 | C9: =①24瓶主母液_纯品μL!B9 -> 戊酸乙酯 | D9: 对应化合物液体纯品 | E9: =①24瓶主母液_纯品μL!H9 -> 473 | F9: =IF(E9>1000,"P1000分次（约"&ROUNDUP(E9/1000,0)&"次）",IF(E9>200,"P1000",IF(E9>20,"P200",IF(E9>10,"P20","P10")))) -> P1000 | G9: =①24瓶主母液_纯品μL!D9 -> 20 | H9: =①24瓶主母液_纯品μL!Q9 -> 19.527 | I9: =IF(H9>10,"先量10mL，再量"&TEXT(H9-10,"0.00")&"mL","一次量"&TEXT(H9,"0.00")&"mL") -> 先量10mL，再量9.53mL | J9: □
A10: M06 | B10: 主液 | C10: =①24瓶主母液_纯品μL!B10 -> 庚酸乙酯 | D10: 对应化合物液体纯品 | E10: =①24瓶主母液_纯品μL!H10 -> 403 | F10: =IF(E10>1000,"P1000分次（约"&ROUNDUP(E10/1000,0)&"次）",IF(E10>200,"P1000",IF(E10>20,"P200",IF(E10>10,"P20","P10")))) -> P1000 | G10: =①24瓶主母液_纯品μL!D10 -> 20 | H10: =①24瓶主母液_纯品μL!Q10 -> 19.597 | I10: =IF(H10>10,"先量10mL，再量"&TEXT(H10-10,"0.00")&"mL","一次量"&TEXT(H10,"0.00")&"mL") -> 先量10mL，再量9.60mL | J10: □
A11: M07 | B11: 主液 | C11: =①24瓶主母液_纯品μL!B11 -> 己酸异戊酯 | D11: 对应化合物液体纯品 | E11: =①24瓶主母液_纯品μL!H11 -> 48 | F11: =IF(E11>1000,"P1000分次（约"&ROUNDUP(E11/1000,0)&"次）",IF(E11>200,"P1000",IF(E11>20,"P200",IF(E11>10,"P20","P10")))) -> P200 | G11: =①24瓶主母液_纯品μL!D11 -> 20 | H11: =①24瓶主母液_纯品μL!Q11 -> 19.952 | I11: =IF(H11>10,"先量10mL，再量"&TEXT(H11-10,"0.00")&"mL","一次量"&TEXT(H11,"0.00")&"mL") -> 先量10mL，再量9.95mL | J11: □
A12: M08 | B12: 主液 | C12: =①24瓶主母液_纯品μL!B12 -> 乙酸异戊酯 | D12: 对应化合物液体纯品 | E12: =①24瓶主母液_纯品μL!H12 -> 945 | F12: =IF(E12>1000,"P1000分次（约"&ROUNDUP(E12/1000,0)&"次）",IF(E12>200,"P1000",IF(E12>20,"P200",IF(E12>10,"P20","P10")))) -> P1000 | G12: =①24瓶主母液_纯品μL!D12 -> 20 | H12: =①24瓶主母液_纯品μL!Q12 -> 19.055 | I12: =IF(H12>10,"先量10mL，再量"&TEXT(H12-10,"0.00")&"mL","一次量"&TEXT(H12,"0.00")&"mL") -> 先量10mL，再量9.06mL | J12: □
A13: M09 | B13: 主液 | C13: =①24瓶主母液_纯品μL!B13 -> 乙醛二乙缩醛 | D13: 对应化合物液体纯品 | E13: =①24瓶主母液_纯品μL!H13 -> 998 | F13: =IF(E13>1000,"P1000分次（约"&ROUNDUP(E13/1000,0)&"次）",IF(E13>200,"P1000",IF(E13>20,"P200",IF(E13>10,"P20","P10")))) -> P1000 | G13: =①24瓶主母液_纯品μL!D13 -> 20 | H13: =①24瓶主母液_纯品μL!Q13 -> 19.002 | I13: =IF(H13>10,"先量10mL，再量"&TEXT(H13-10,"0.00")&"mL","一次量"&TEXT(H13,"0.00")&"mL") -> 先量10mL，再量9.00mL | J13: □
A14: M10 | B14: 主液 | C14: =①24瓶主母液_纯品μL!B14 -> 异丁酸乙酯 | D14: 对应化合物液体纯品 | E14: =①24瓶主母液_纯品μL!H14 -> 238 | F14: =IF(E14>1000,"P1000分次（约"&ROUNDUP(E14/1000,0)&"次）",IF(E14>200,"P1000",IF(E14>20,"P200",IF(E14>10,"P20","P10")))) -> P1000 | G14: =①24瓶主母液_纯品μL!D14 -> 20 | H14: =①24瓶主母液_纯品μL!Q14 -> 19.762 | I14: =IF(H14>10,"先量10mL，再量"&TEXT(H14-10,"0.00")&"mL","一次量"&TEXT(H14,"0.00")&"mL") -> 先量10mL，再量9.76mL | J14: □
A15: M11 | B15: 主液 | C15: =①24瓶主母液_纯品μL!B15 -> 癸酸乙酯 | D15: 对应化合物液体纯品 | E15: =①24瓶主母液_纯品μL!H15 -> 95 | F15: =IF(E15>1000,"P1000分次（约"&ROUNDUP(E15/1000,0)&"次）",IF(E15>200,"P1000",IF(E15>20,"P200",IF(E15>10,"P20","P10")))) -> P200 | G15: =①24瓶主母液_纯品μL!D15 -> 20 | H15: =①24瓶主母液_纯品μL!Q15 -> 19.905 | I15: =IF(H15>10,"先量10mL，再量"&TEXT(H15-10,"0.00")&"mL","一次量"&TEXT(H15,"0.00")&"mL") -> 先量10mL，再量9.91mL | J15: □
A16: M12 | B16: 主液 | C16: =①24瓶主母液_纯品μL!B16 -> 己酸 | D16: 对应化合物液体纯品 | E16: =①24瓶主母液_纯品μL!H16 -> 2228 | F16: =IF(E16>1000,"P1000分次（约"&ROUNDUP(E16/1000,0)&"次）",IF(E16>200,"P1000",IF(E16>20,"P200",IF(E16>10,"P20","P10")))) -> P1000分次（约3次） | G16: =①24瓶主母液_纯品μL!D16 -> 20 | H16: =①24瓶主母液_纯品μL!Q16 -> 17.772 | I16: =IF(H16>10,"先量10mL，再量"&TEXT(H16-10,"0.00")&"mL","一次量"&TEXT(H16,"0.00")&"mL") -> 先量10mL，再量7.77mL | J16: □
... A28: M24 | B28: 主液 | C28: =①24瓶主母液_纯品μL!B28 -> 壬酸乙酯 | D28: 对应化合物液体纯品 | E28: =①24瓶主母液_纯品μL!H28 -> 124 | F28: =IF(E28>1000,"P1000分次（约"&ROUNDUP(E28/1000,0)&"次）",IF(E28>200,"P1000",IF(E28>20,"P200",IF(E28>10,"P20","P10")))) -> P200 | G28: =①24瓶主母液_纯品μL!D28 -> 20 | H28: =①24瓶主母液_纯品μL!Q28 -> 19.876 | I28: =IF(H28>10,"先量10mL，再量"&TEXT(H28-10,"0.00")&"mL","一次量"&TEXT(H28,"0.00")&"mL") -> 先量10mL，再量9.88mL | J28: □
A29: D01 | B29: 一次稀释液 | C29: =②7瓶一次稀释液!B5 -> 异戊酸乙酯 | D29: 对应的主母液 | E29: =②7瓶一次稀释液!G5 -> 200 | F29: =IF(E29>1000,"P1000分次（约"&ROUNDUP(E29/1000,0)&"次）",IF(E29>200,"P1000",IF(E29>20,"P200",IF(E29>10,"P20","P10")))) -> P200 | G29: =②7瓶一次稀释液!F5 -> 20 | H29: =②7瓶一次稀释液!L5 -> 19.8 | I29: =IF(H29>10,"先量10mL，再量"&TEXT(H29-10,"0.00")&"mL","一次量"&TEXT(H29,"0.00")&"mL") -> 先量10mL，再量9.80mL | J29: □
A30: D02 | B30: 一次稀释液 | C30: =②7瓶一次稀释液!B6 -> 丁酸乙酯 | D30: 对应的主母液 | E30: =②7瓶一次稀释液!G6 -> 4000 | F30: =IF(E30>1000,"P1000分次（约"&ROUNDUP(E30/1000,0)&"次）",IF(E30>200,"P1000",IF(E30>20,"P200",IF(E30>10,"P20","P10")))) -> P1000分次（约4次） | G30: =②7瓶一次稀释液!F6 -> 20 | H30: =②7瓶一次稀释液!L6 -> 16 | I30: =IF(H30>10,"先量10mL，再量"&TEXT(H30-10,"0.00")&"mL","一次量"&TEXT(H30,"0.00")&"mL") -> 先量10mL，再量6.00mL | J30: □
A31: D03 | B31: 一次稀释液 | C31: =②7瓶一次稀释液!B7 -> 戊酸乙酯 | D31: 对应的主母液 | E31: =②7瓶一次稀释液!G7 -> 2000 | F31: =IF(E31>1000,"P1000分次（约"&ROUNDUP(E31/1000,0)&"次）",IF(E31>200,"P1000",IF(E31>20,"P200",IF(E31>10,"P20","P10")))) -> P1000分次（约2次） | G31: =②7瓶一次稀释液!F7 -> 20 | H31: =②7瓶一次稀释液!L7 -> 18 | I31: =IF(H31>10,"先量10mL，再量"&TEXT(H31-10,"0.00")&"mL","一次量"&TEXT(H31,"0.00")&"mL") -> 先量10mL，再量8.00mL | J31: □
A32: D04 | B32: 一次稀释液 | C32: =②7瓶一次稀释液!B8 -> 乙酸异戊酯 | D32: 对应的主母液 | E32: =②7瓶一次稀释液!G8 -> 1000 | F32: =IF(E32>1000,"P1000分次（约"&ROUNDUP(E32/1000,0)&"次）",IF(E32>200,"P1000",IF(E32>20,"P200",IF(E32>10,"P20","P10")))) -> P1000 | G32: =②7瓶一次稀释液!F8 -> 20 | H32: =②7瓶一次稀释液!L8 -> 19 | I32: =IF(H32>10,"先量10mL，再量"&TEXT(H32-10,"0.00")&"mL","一次量"&TEXT(H32,"0.00")&"mL") -> 先量10mL，再量9.00mL | J32: □
A33: D05 | B33: 一次稀释液 | C33: =②7瓶一次稀释液!B9 -> 异丁酸乙酯 | D33: 对应的主母液 | E33: =②7瓶一次稀释液!G9 -> 2000 | F33: =IF(E33>1000,"P1000分次（约"&ROUNDUP(E33/1000,0)&"次）",IF(E33>200,"P1000",IF(E33>20,"P200",IF(E33>10,"P20","P10")))) -> P1000分次（约2次） | G33: =②7瓶一次稀释液!F9 -> 20 | H33: =②7瓶一次稀释液!L9 -> 18 | I33: =IF(H33>10,"先量10mL，再量"&TEXT(H33-10,"0.00")&"mL","一次量"&TEXT(H33,"0.00")&"mL") -> 先量10mL，再量8.00mL | J33: □
A34: D06 | B34: 一次稀释液 | C34: =②7瓶一次稀释液!B10 -> 苯乙酸乙酯 | D34: 对应的主母液 | E34: =②7瓶一次稀释液!G10 -> 1000 | F34: =IF(E34>1000,"P1000分次（约"&ROUNDUP(E34/1000,0)&"次）",IF(E34>200,"P1000",IF(E34>20,"P200",IF(E34>10,"P20","P10")))) -> P1000 | G34: =②7瓶一次稀释液!F10 -> 20 | H34: =②7瓶一次稀释液!L10 -> 19 | I34: =IF(H34>10,"先量10mL，再量"&TEXT(H34-10,"0.00")&"mL","一次量"&TEXT(H34,"0.00")&"mL") -> 先量10mL，再量9.00mL | J34: □
A35: D07 | B35: 一次稀释液 | C35: =②7瓶一次稀释液!B11 -> 1-丁醇 | D35: 对应的主母液 | E35: =②7瓶一次稀释液!G11 -> 1000 | F35: =IF(E35>1000,"P1000分次（约"&ROUNDUP(E35/1000,0)&"次）",IF(E35>200,"P1000",IF(E35>20,"P200",IF(E35>10,"P20","P10")))) -> P1000 | G35: =②7瓶一次稀释液!F11 -> 20 | H35: =②7瓶一次稀释液!L11 -> 19 | I35: =IF(H35>10,"先量10mL，再量"&TEXT(H35-10,"0.00")&"mL","一次量"&TEXT(H35,"0.00")&"mL") -> 先量10mL，再量9.00mL | J35: □
A38: 重要：20mL棕色瓶如果正好装满，混匀空间不足；建议先在干净、密闭性良好的更大容器中混匀，再装瓶，或选更大规格棕色瓶。
