Workbook

Sheet 0-参数
A1: 参数（可修改，下游自动重算）
A3: 稀释溶剂 | B3: 95% vol 食品级乙醇 | C3: ★95%乙醇，溶解度远好于52%
A4: 每份重构酒终体积 V | B4: 20 | C4: mL ← 20 mL 量级
A5: 纯品纯度 | B5: 0.97 | C5: ≥97%
A6: 最小移液体积 | B6: 20 | C6: μL
A7: 最大移液体积 | B7: 2500 | C7: μL
A8: 设计规模 | B8: 64 | C8: 满因子 4×4×4
A9: 每化合物出现次数 | B9: 16 | C9: 个
A11: 换算公式
A12: 母液纯品取用量(μL) = 母液浓度(μg/L) × 母液配制体积(L) ÷ 1000 ÷ 纯度 ÷ 密度(g/mL)
A13: 工作液：取母液 母液浓度÷工作液浓度 × 工作液配制体积(mL) μL，用95%乙醇定容
A14: 添加体积(μL) = 目标浓度(μg/L) × 20 mL × 1000 ÷ 所用级别浓度(μg/L)
A15: ★ ppb 目标值与 Excel「重构分析」一致，只是终体积改成 20 mL，质量为原来的 1/5。
A16: ★ 本表只给到「添加体积」为止，不含最终酒精度回调 —— 由你另行定容处理。

Sheet 1-母液配制表(体积法)
A1: 母液 / 工作液配制表（20 mL 重构 · 95% 乙醇）
A2: 黄底格可改（浓度、密度）。疏水酯母液最高 30.0 mg/mL —— 比原 52%乙醇下实测不溶的 100 mg/mL 低 3.3 倍。
A4: 化合物 | B4: CAS | C4: logP | D4: 密度ρ | E4: 级别 | F4: 浓度 (μg/L) | G4: 配制 (mL) | H4: 瓶子 | I4: ★配制操作 | J4: 用量 (μL)
A5: 异戊酸乙酯 | B5: 108-64-5 | C5: 2 | D5: 0.864
E6: 母液 | F6: 15000000 | G6: 20 | H6: 20 mL | I6: 取纯品 357961.1 μL + 95%乙醇定容 | J6: =F6*G6/1000/1000/'0-参数'!$B$5/D5
E7: 工作液1 | F7: 120000 | G7: 20 | H7: 20 mL | I7: 取母液 2500 μL + 95%乙醇定容 | J7: 2500
A8: 丁酸乙酯 | B8: 105-54-4 | C8: 1.8 | D8: 0.874
E9: 母液 | F9: 60000000 | G9: 20 | H9: 20 mL | I9: 取纯品 1415461.6 μL + 95%乙醇定容 | J9: =F9*G9/1000/1000/'0-参数'!$B$5/D8
E10: 工作液1 | F10: 480000 | G10: 20 | H10: 20 mL | I10: 取母液 2500 μL + 95%乙醇定容 | J10: 2500
A11: 乙酸乙酯 | B11: 141-78-6 | C11: -0.3 | D11: 0.9
E12: 母液 | F12: 400000000 | G12: 20 | H12: 20 mL | I12: 取纯品 9163803.0 μL + 95%乙醇定容 | J12: =F12*G12/1000/1000/'0-参数'!$B$5/D11
A13: 辛酸乙酯 | B13: 106-32-1 | C13: 3.8 | D13: 0.867
E14: 母液 | F14: 3000000 | G14: 100 | H14: 100 mL | I14: 取纯品 356722.4 μL + 95%乙醇定容 | J14: =F14*G14/1000/1000/'0-参数'!$B$5/D13
A15: 戊酸乙酯 | B15: 539-82-2 | C15: 2.9 | D15: 0.873
E16: 母液 | F16: 30000000 | G16: 20 | H16: 20 mL | I16: 取纯品 708541.5 μL + 95%乙醇定容 | J16: =F16*G16/1000/1000/'0-参数'!$B$5/D15
E17: 工作液1 | F17: 240000 | G17: 100 | H17: 100 mL | I17: 取母液 12500 μL + 95%乙醇定容 | J17: 12500
A18: 庚酸乙酯 | B18: 106-30-9 | C18: 3.6 | D18: 0.87
E19: 母液 | F19: 8000000 | G19: 20 | H19: 20 mL | I19: 取纯品 189595.9 μL + 95%乙醇定容 | J19: =F19*G19/1000/1000/'0-参数'!$B$5/D18
A20: 己酸异戊脂 | B20: 2198-61-0 | C20: 3.9 | D20: 0.861
E21: 母液 | F21: 30000000 | G21: 20 | H21: 20 mL | I21: 取纯品 718416.6 μL + 95%乙醇定容 | J21: =F21*G21/1000/1000/'0-参数'!$B$5/D20
E22: 工作液1 | F22: 240000 | G22: 20 | H22: 20 mL | I22: 取母液 2500 μL + 95%乙醇定容 | J22: 2500
A23: 乙酸异戊酯 | B23: 123-92-2 | C23: 2.8 | D23: 0.87
E24: 母液 | F24: 30000000 | G24: 20 | H24: 20 mL | I24: 取纯品 710984.7 μL + 95%乙醇定容 | J24: =F24*G24/1000/1000/'0-参数'!$B$5/D23
E25: 工作液1 | F25: 240000 | G25: 100 | H25: 100 mL | I25: 取母液 12500 μL + 95%乙醇定容 | J25: 12500
A26: 乙醛二乙缩醛 | B26: 105-57-7 | C26: 1.1 | D26: 0.827
E27: 母液 | F27: 20000000 | G27: 20 | H27: 20 mL | I27: 取纯品 498635.0 μL + 95%乙醇定容 | J27: =F27*G27/1000/1000/'0-参数'!$B$5/D26
A28: 异丁酸乙酯 | B28: 97-62-1 | C28: 2 | D28: 0.865
E29: 母液 | F29: 30000000 | G29: 20 | H29: 20 mL | I29: 取纯品 715094.5 μL + 95%乙醇定容 | J29: =F29*G29/1000/1000/'0-参数'!$B$5/D28
E30: 工作液1 | F30: 240000 | G30: 20 | H30: 20 mL | I30: 取母液 2500 μL + 95%乙醇定容 | J30: 2500
A31: 癸酸乙酯 | B31: 110-38-3 | C31: 4.4 | D31: 0.866
E32: 母液 | F32: 2000000 | G32: 20 | H32: 20 mL | I32: 取纯品 47617.9 μL + 95%乙醇定容 | J32: =F32*G32/1000/1000/'0-参数'!$B$5/D31
A33: 己酸己酯 | B33: 123-49-9 | C33: 4.3 | D33: 0.859
E34: 母液 | F34: 30000000 | G34: 20 | H34: 20 mL | I34: 取纯品 720089.3 μL + 95%乙醇定容 | J34: =F34*G34/1000/1000/'0-参数'!$B$5/D33
E35: 工作液1 | F35: 240000 | G35: 100 | H35: 100 mL | I35: 取母液 12500 μL + 95%乙醇定容 | J35: 12500
A36: 苯乙酸乙酯 | B36: 101-97-3 | C36: 2.5 | D36: 1.03
E37: 母液 | F37: 60000000 | G37: 20 | H37: 20 mL | I37: 取纯品 1201081.0 μL + 95%乙醇定容 | J37: =F37*G37/1000/1000/'0-参数'!$B$5/D36
E38: 工作液1 | F38: 480000 | G38: 20 | H38: 20 mL | I38: 取母液 2500 μL + 95%乙醇定容 | J38: 2500
A39: 1-丁醇 | B39: 71-36-3 | C39: 2 | D39: 0.81
E40: 母液 | F40: 150000000 | G40: 20 | H40: 20 mL | I40: 取纯品 3818251.2 μL + 95%乙醇定容 | J40: =F40*G40/1000/1000/'0-参数'!$B$5/D39
E41: 工作液1 | F41: 1200000 | G41: 100 | H41: 100 mL | I41: 取母液 12500 μL + 95%乙醇定容 | J41: 12500
...

Sheet 2-添加体积表(μL)
A1: 各基底重构酒 添加体积对照表（终体积 20 mL，μL）
A3: 化合物 | B3: 乳酸乙酯 基底 | C3: 己酸丁酯 基底 | D3: 棕榈酸乙酯 基底 | E3: 丁酸异戊酯 基底 | F3: Cmin ppb | G3: Cmax ppb
A4: 异戊酸乙酯 | B4: 234.5 | C4: 299 | D4: 150 | E4: 25 | F4: 150 | G4: 176050
A5: 丁酸乙酯 | B5: 313.5 | C5: 21 | D5: 624 | E5: 100 | F5: 2400 | G5: 940000
A6: 乙酸乙酯 | B6: 233 | C6: 88 | D6: 29 | E6: 20 | F6: 400000 | G6: 4661800
A7: 辛酸乙酯 | B7: 1645 | C7: 120 | D7: 24 | E7: — | F7: 3600 | G7: 247040
A8: 戊酸乙酯 | B8: 251 | C8: 1015 | D8: 312.5 | E8: 62 | F8: 750 | G8: 376550
A9: 庚酸乙酯 | B9: 872 | C9: 82 | D9: 29 | E9: 20 | F9: 8000 | G9: 348671
A10: 己酸异戊脂 | B10: 38 | C10: 200 | D10: 42 | E10: — | F10: 500 | G10: 57280
A11: 乙酸异戊酯 | B11: 320.5 | C11: 1125 | D11: 225 | E11: 85 | F11: 1025 | G11: 480980
A12: 乙醛二乙缩醛 | B12: 784 | C12: 90 | D12: 24 | E12: — | F12: 24000 | G12: 784300
A13: 异丁酸乙酯 | B13: 129 | C13: 414 | D13: 146 | E13: 25 | F13: 300 | G13: 193560
A14: 癸酸乙酯 | B14: 562 | C14: 250 | D14: 75 | E14: 21 | F14: 2117 | G14: 56115
A15: 己酸己酯 | B15: 130 | C15: 1000 | D15: 784 | E15: 200 | F15: 2400 | G15: 195030
A16: 苯乙酸乙酯 | B16: 119 | C16: 260.5 | D16: 82 | E16: 42 | F16: 1000 | G16: 357110
A17: 1-丁醇 | B17: 64 | C17: 2000 | D17: 21 | E17: — | F17: 1282 | G17: 480980
A18: 1-己醇 | B18: 497.5 | C18: 85 | D18: 40 | E18: 21 | F18: 16000 | G18: 373000
A19: 壬酸乙酯 | B19: 79 | C19: 916 | D19: 183.5 | E19: 109 | F19: 1305 | G19: 118700
A20: 己酸 | B20: 620 | C20: 240 | D20: 52 | E20: 20 | F20: 50000 | G20: 1552320
A21: 异丁酸 | B21: 820 | C21: 150 | D21: 20 | E21: — | F21: 3000 | G21: 123135
A22: 戊酸 | B22: 111 | C22: 1250 | D22: 358.5 | E22: 100 | F22: 2400 | G22: 333536
A23: 辛酸 | B23: 1670 | C23: 150 | D23: 43 | E23: 24 | F23: 4800 | G23: 333536
A24: 庚酸 | B24: 491 | C24: 144 | D24: 40 | E24: 22 | F24: 5495 | G24: 122710
A25: 丁酸 | B25: 734 | C25: 146.5 | D25: 55 | E25: 20 | F25: 15000 | G25: 550200
A26: 乙酸 | B26: 288 | C26: 192 | D26: 51 | E26: 23 | F26: 143377 | G26: 1800500
A27: 异戊酸/3-甲基丁酸 | B27: 430.5 | C27: 160 | D27: 77 | E27: 24 | F27: 1800 | G27: 32300
A28: 添加体积合计 (μL) | B28: 11438 | C28: 10400 | D28: 3489 | E28: 964
A29: 占 20 mL 体积比例 | B29: 57.2 | C29: 52 | D29: 17.4 | E29: 4.8
A30: 需补加 95%乙醇 (mL) | B30: 8.56 | C30: 9.6 | D30: 16.51 | E30: 19.04

Sheet 3-浓度与溶解度
A1: 母液浓度与溶解度对照（95% 乙醇 · 20 mL 重构）
A3: 化合物 | B3: logP | C3: 浓度跨度 | D3: ★母液 mg/mL | E3: 工作液 mg/mL | F3: 水中溶解度 mg/L | G3: 说明
A4: 乙酸乙酯 | B4: -0.3 | C4: 11.7 | D4: 400 | E4: — | F4: 6700 | G4: 与乙醇互溶，无溶解度顾虑
A5: 1-丁醇 | B5: 2 | C5: 375.2 | D5: 150 | E5: 1.2 | F5: 互溶 | G5: 与乙醇互溶，无溶解度顾虑
A6: 乙酸 | B6: 2 | C6: 12.6 | D6: 125 | E6: — | F6: — | G6: 与乙醇互溶，无溶解度顾虑
A7: 丁酸乙酯 | B7: 1.8 | C7: 391.7 | D7: 60 | E7: 0.48 | F7: 6700 | G7: 中等
A8: 苯乙酸乙酯 | B8: 2.5 | C8: 357.1 | D8: 60 | E8: 0.48 | F8: ~2000 | G8: 中等
A9: 戊酸 | B9: 2 | C9: 139 | D9: 60 | E9: 0.48 | F9: — | G9: 中等
A10: 己酸 | B10: 1.9 | C10: 31 | D10: 50 | E10: — | F10: — | G10: 中等
A11: 戊酸乙酯 | B11: 2.9 | C11: 502.1 | D11: 30 | E11: 0.24 | F11: ~600 | G11: 疏水酯，已压到 30
A12: 己酸异戊脂 | B12: 3.9 | C12: 114.6 | D12: 30 | E12: 0.24 | F12: ~1 | G12: 疏水酯，已压到 30
A13: 乙酸异戊酯 | B13: 2.8 | C13: 469.2 | D13: 30 | E13: 0.24 | F13: ~30 | G13: 疏水酯，已压到 30
A14: 异丁酸乙酯 | B14: 2 | C14: 645.2 | D14: 30 | E14: 0.24 | F14: — | G14: 中等
A15: 己酸己酯 | B15: 4.3 | C15: 81.3 | D15: 30 | E15: 0.24 | F15: 0.95 | G15: 疏水酯，已压到 30
A16: 壬酸乙酯 | B16: 3.7 | C16: 91 | D16: 30 | E16: 0.24 | F16: ~2 | G16: 疏水酯，已压到 30
A17: 乙醛二乙缩醛 | B17: 1.1 | C17: 32.7 | D17: 20 | E17: — | F17: 46000 | G17: 水溶性好
A18: 异戊酸乙酯 | B18: 2 | C18: 1173.7 | D18: 15 | E18: 0.12 | F18: — | G18: 中等
A19: 1-己醇 | B19: 2 | C19: 23.3 | D19: 15 | E19: — | F19: 互溶 | G19: 与乙醇互溶，无溶解度顾虑
A20: 丁酸 | B20: 2 | C20: 36.7 | D20: 15 | E20: — | F20: — | G20: 中等
A21: 庚酸乙酯 | B21: 3.6 | C21: 43.6 | D21: 8 | E21: — | F21: 126 | G21: 疏水酯，已压到 8
A22: 庚酸 | B22: 2 | C22: 22.3 | D22: 5 | E22: — | F22: — | G22: 中等
A23: 辛酸 | B23: 3 | C23: 69.5 | D23: 4 | E23: — | F23: ~680 | G23: 疏水酯，已压到 4
A24: 辛酸乙酯 | B24: 3.8 | C24: 68.6 | D24: 3 | E24: — | F24: ~2 | G24: 疏水酯，已压到 3
A25: 异丁酸 | B25: 2 | C25: 41 | D25: 3 | E25: — | F25: — | G25: 中等
A26: 癸酸乙酯 | B26: 4.4 | C26: 26.5 | D26: 2 | E26: — | F26: 15.9 | G26: 疏水酯，已压到 2
A27: 异戊酸/3-甲基丁酸 | B27: 2 | C27: 17.9 | D27: 1.5 | E27: — | F27: — | G27: 中等

Sheet 4-操作与保存说明
A1: 【一、20 mL 重构版要点】
A2: ppb 目标值不变
A3: 为什么用量少一半还能用
A4: 疏水酯母液
A5: 全局最高
A7: 【二、能直接配成一支吗？】
A8: 结论
A9: 为什么那 11 个不行
A10: 具体是哪几个
A11: 怎么配工作液
A13: 【三、⚠ 酒精度会被推高，由你处理】
A14: 问题
... A25: 乙酸乙酯极易挥发（沸点 77°C），务必冷凉密封、用前复测浓度；乙醛二乙缩醛为缩醛，避免接触酸式玻璃器皿。
